2021-10-25 08:41:35.414 | INFO     |  5870 | __main__:main:46 | Starting Audio Service
2021-10-25 08:41:35.415 | INFO     |  5870 | mycroft.messagebus.load_config:load_message_bus_config:33 | Loading message bus configs
2021-10-25 08:41:35.418 | INFO     |  5870 | mycroft_bus_client.client.client | Connected
2021-10-25 08:41:35.421 | INFO     |  5870 | mycroft.util.process_utils:start_message_bus_client:155 | Connected to messagebus
2021-10-25 08:41:35.428 | WARNING  |  5870 | mycroft.tts.tts:clear_cache:428 | This method is deprecated, use TextToSpeechCache.clear
2021-10-25 08:41:35.683 | ERROR    |  5870 | mycroft.tts.mimic_tts:validate_connection:226 | Mimic executable not found
2021-10-25 08:41:35.684 | ERROR    |  5870 | mycroft.tts.tts:create:625 | The TTS could not be loaded.
Traceback (most recent call last):
  File "/opt/mycroft-core/mycroft/tts/mimic_tts.py", line 221, in validate_connection
    subprocess.call([mimic_bin, '--version'])
  File "/opt/hostedtoolcache/Python/3.7.12/x64/lib/python3.7/subprocess.py", line 339, in call
    with Popen(*popenargs, **kwargs) as p:
  File "/opt/hostedtoolcache/Python/3.7.12/x64/lib/python3.7/subprocess.py", line 800, in __init__
    restore_signals, start_new_session)
  File "/opt/hostedtoolcache/Python/3.7.12/x64/lib/python3.7/subprocess.py", line 1465, in _execute_child
    executable = os.fsencode(executable)
  File "/opt/hostedtoolcache/Python/3.7.12/x64/lib/python3.7/os.py", line 812, in fsencode
    filename = fspath(filename)  # Does type-checking of `filename`.
TypeError: expected str, bytes or os.PathLike object, not NoneType

The above exception was the direct cause of the following exception:

Traceback (most recent call last):
  File "/opt/mycroft-core/mycroft/tts/tts.py", line 614, in create
    tts.validator.validate()
  File "/opt/mycroft-core/mycroft/tts/tts.py", line 500, in validate
    self.validate_connection()
  File "/opt/mycroft-core/mycroft/tts/mimic_tts.py", line 229, in validate_connection
    from err
Exception: Mimic was not found. Run install-mimic.sh to install it.
2021-10-25 08:41:35.772 | ERROR    |  5870 | __main__:on_error:37 | Audio service failed to launch (Exception('Mimic was not found. Run install-mimic.sh to install it.')).
2021-10-25 08:41:49.438 | ERROR    |  5870 | mycroft.audio.speech:handle_speak:99 | Error in mute_and_speak
Traceback (most recent call last):
  File "/opt/mycroft-core/mycroft/audio/speech.py", line 95, in handle_speak
    mute_and_speak(chunk, ident, listen)
  File "/opt/mycroft-core/mycroft/audio/speech.py", line 120, in mute_and_speak
    tts.playback.stop()
AttributeError: 'NoneType' object has no attribute 'playback'
2021-10-25 08:42:20.057 | ERROR    |  5870 | mycroft.audio.speech:handle_speak:99 | Error in mute_and_speak
Traceback (most recent call last):
  File "/opt/mycroft-core/mycroft/audio/speech.py", line 95, in handle_speak
    mute_and_speak(chunk, ident, listen)
  File "/opt/mycroft-core/mycroft/audio/speech.py", line 120, in mute_and_speak
    tts.playback.stop()
AttributeError: 'NoneType' object has no attribute 'playback'
2021-10-25 08:42:20.057 | ERROR    |  5870 | mycroft.audio.speech:handle_speak:99 | Error in mute_and_speak
Traceback (most recent call last):
  File "/opt/mycroft-core/mycroft/audio/speech.py", line 95, in handle_speak
    mute_and_speak(chunk, ident, listen)
  File "/opt/mycroft-core/mycroft/audio/speech.py", line 120, in mute_and_speak
    tts.playback.stop()
AttributeError: 'NoneType' object has no attribute 'playback'
2021-10-25 08:42:41.433 | ERROR    |  5870 | websocket | error from callback <bound method MessageBusClient.on_message of <mycroft.messagebus.client.client.MessageBusClient object at 0x7f0dc65a3810>>: cannot schedule new futures after shutdown
2021-10-25 08:42:41.433 | ERROR    |  5870 | websocket | error from callback <bound method MessageBusClient.on_message of <mycroft.messagebus.client.client.MessageBusClient object at 0x7f0dc65a3810>>: cannot schedule new futures after shutdown
2021-10-25 08:42:41.434 | ERROR    |  5870 | websocket | error from callback <bound method MessageBusClient.on_message of <mycroft.messagebus.client.client.MessageBusClient object at 0x7f0dc65a3810>>: cannot schedule new futures after shutdown
2021-10-25 08:42:41.434 | ERROR    |  5870 | websocket | error from callback <bound method MessageBusClient.on_message of <mycroft.messagebus.client.client.MessageBusClient object at 0x7f0dc65a3810>>: cannot schedule new futures after shutdown
2021-10-25 08:42:41.434 | ERROR    |  5870 | websocket | error from callback <bound method MessageBusClient.on_message of <mycroft.messagebus.client.client.MessageBusClient object at 0x7f0dc65a3810>>: cannot schedule new futures after shutdown
2021-10-25 08:42:41.435 | ERROR    |  5870 | websocket | error from callback <bound method MessageBusClient.on_message of <mycroft.messagebus.client.client.MessageBusClient object at 0x7f0dc65a3810>>: cannot schedule new futures after shutdown
2021-10-25 08:42:41.435 | ERROR    |  5870 | websocket | error from callback <bound method MessageBusClient.on_message of <mycroft.messagebus.client.client.MessageBusClient object at 0x7f0dc65a3810>>: cannot schedule new futures after shutdown
2021-10-25 08:42:41.435 | ERROR    |  5870 | websocket | error from callback <bound method MessageBusClient.on_message of <mycroft.messagebus.client.client.MessageBusClient object at 0x7f0dc65a3810>>: cannot schedule new futures after shutdown
2021-10-25 08:42:41.436 | ERROR    |  5870 | websocket | error from callback <bound method MessageBusClient.on_message of <mycroft.messagebus.client.client.MessageBusClient object at 0x7f0dc65a3810>>: cannot schedule new futures after shutdown
2021-10-25 08:42:41.436 | ERROR    |  5870 | websocket | error from callback <bound method MessageBusClient.on_message of <mycroft.messagebus.client.client.MessageBusClient object at 0x7f0dc65a3810>>: cannot schedule new futures after shutdown
2021-10-25 08:42:41.436 | ERROR    |  5870 | websocket | error from callback <bound method MessageBusClient.on_message of <mycroft.messagebus.client.client.MessageBusClient object at 0x7f0dc65a3810>>: cannot schedule new futures after shutdown
2021-10-25 08:42:41.436 | ERROR    |  5870 | websocket | error from callback <bound method MessageBusClient.on_message of <mycroft.messagebus.client.client.MessageBusClient object at 0x7f0dc65a3810>>: cannot schedule new futures after shutdown
2021-10-25 08:42:41.438 | ERROR    |  5870 | websocket | error from callback <bound method MessageBusClient.on_message of <mycroft.messagebus.client.client.MessageBusClient object at 0x7f0dc65a3810>>: cannot schedule new futures after shutdown
2021-10-25 08:43:01.361 | INFO     |  7494 | __main__:main:46 | Starting Audio Service
2021-10-25 08:43:01.362 | INFO     |  7494 | mycroft.messagebus.load_config:load_message_bus_config:33 | Loading message bus configs
2021-10-25 08:43:01.365 | INFO     |  7494 | mycroft_bus_client.client.client | Connected
2021-10-25 08:43:01.366 | INFO     |  7494 | mycroft.util.process_utils:start_message_bus_client:155 | Connected to messagebus
2021-10-25 08:43:01.369 | WARNING  |  7494 | mycroft.tts.tts:clear_cache:428 | This method is deprecated, use TextToSpeechCache.clear
2021-10-25 08:43:01.514 | ERROR    |  7494 | mycroft.tts.mimic_tts:validate_connection:226 | Mimic executable not found
2021-10-25 08:43:01.515 | ERROR    |  7494 | mycroft.tts.tts:create:625 | The TTS could not be loaded.
Traceback (most recent call last):
  File "/opt/mycroft-core/mycroft/tts/mimic_tts.py", line 221, in validate_connection
    subprocess.call([mimic_bin, '--version'])
  File "/opt/hostedtoolcache/Python/3.7.12/x64/lib/python3.7/subprocess.py", line 339, in call
    with Popen(*popenargs, **kwargs) as p:
  File "/opt/hostedtoolcache/Python/3.7.12/x64/lib/python3.7/subprocess.py", line 800, in __init__
    restore_signals, start_new_session)
  File "/opt/hostedtoolcache/Python/3.7.12/x64/lib/python3.7/subprocess.py", line 1465, in _execute_child
    executable = os.fsencode(executable)
  File "/opt/hostedtoolcache/Python/3.7.12/x64/lib/python3.7/os.py", line 812, in fsencode
    filename = fspath(filename)  # Does type-checking of `filename`.
TypeError: expected str, bytes or os.PathLike object, not NoneType

The above exception was the direct cause of the following exception:

Traceback (most recent call last):
  File "/opt/mycroft-core/mycroft/tts/tts.py", line 614, in create
    tts.validator.validate()
  File "/opt/mycroft-core/mycroft/tts/tts.py", line 500, in validate
    self.validate_connection()
  File "/opt/mycroft-core/mycroft/tts/mimic_tts.py", line 229, in validate_connection
    from err
Exception: Mimic was not found. Run install-mimic.sh to install it.
2021-10-25 08:43:01.516 | ERROR    |  7494 | __main__:on_error:37 | Audio service failed to launch (Exception('Mimic was not found. Run install-mimic.sh to install it.')).
2021-10-25 08:43:03.407 | ERROR    |  7494 | mycroft.audio.speech:handle_speak:99 | Error in mute_and_speak
Traceback (most recent call last):
  File "/opt/mycroft-core/mycroft/audio/speech.py", line 95, in handle_speak
    mute_and_speak(chunk, ident, listen)
  File "/opt/mycroft-core/mycroft/audio/speech.py", line 120, in mute_and_speak
    tts.playback.stop()
AttributeError: 'NoneType' object has no attribute 'playback'
2021-10-25 08:43:03.793 | ERROR    |  7494 | mycroft.audio.speech:handle_speak:99 | Error in mute_and_speak
Traceback (most recent call last):
  File "/opt/mycroft-core/mycroft/audio/speech.py", line 95, in handle_speak
    mute_and_speak(chunk, ident, listen)
  File "/opt/mycroft-core/mycroft/audio/speech.py", line 120, in mute_and_speak
    tts.playback.stop()
AttributeError: 'NoneType' object has no attribute 'playback'
2021-10-25 08:43:04.143 | ERROR    |  7494 | mycroft.audio.speech:handle_speak:99 | Error in mute_and_speak
Traceback (most recent call last):
  File "/opt/mycroft-core/mycroft/audio/speech.py", line 95, in handle_speak
    mute_and_speak(chunk, ident, listen)
  File "/opt/mycroft-core/mycroft/audio/speech.py", line 120, in mute_and_speak
    tts.playback.stop()
AttributeError: 'NoneType' object has no attribute 'playback'
2021-10-25 08:43:04.531 | ERROR    |  7494 | mycroft.audio.speech:handle_speak:99 | Error in mute_and_speak
Traceback (most recent call last):
  File "/opt/mycroft-core/mycroft/audio/speech.py", line 95, in handle_speak
    mute_and_speak(chunk, ident, listen)
  File "/opt/mycroft-core/mycroft/audio/speech.py", line 120, in mute_and_speak
    tts.playback.stop()
AttributeError: 'NoneType' object has no attribute 'playback'
2021-10-25 08:43:05.555 | ERROR    |  7494 | mycroft.audio.speech:handle_speak:99 | Error in mute_and_speak
Traceback (most recent call last):
  File "/opt/mycroft-core/mycroft/audio/speech.py", line 95, in handle_speak
    mute_and_speak(chunk, ident, listen)
  File "/opt/mycroft-core/mycroft/audio/speech.py", line 120, in mute_and_speak
    tts.playback.stop()
AttributeError: 'NoneType' object has no attribute 'playback'
2021-10-25 08:43:13.799 | ERROR    |  7494 | mycroft.audio.speech:handle_speak:99 | Error in mute_and_speak
Traceback (most recent call last):
  File "/opt/mycroft-core/mycroft/audio/speech.py", line 95, in handle_speak
    mute_and_speak(chunk, ident, listen)
  File "/opt/mycroft-core/mycroft/audio/speech.py", line 120, in mute_and_speak
    tts.playback.stop()
AttributeError: 'NoneType' object has no attribute 'playback'
2021-10-25 08:43:14.165 | ERROR    |  7494 | mycroft.audio.speech:handle_speak:99 | Error in mute_and_speak
Traceback (most recent call last):
  File "/opt/mycroft-core/mycroft/audio/speech.py", line 95, in handle_speak
    mute_and_speak(chunk, ident, listen)
  File "/opt/mycroft-core/mycroft/audio/speech.py", line 120, in mute_and_speak
    tts.playback.stop()
AttributeError: 'NoneType' object has no attribute 'playback'
2021-10-25 08:43:14.555 | ERROR    |  7494 | mycroft.audio.speech:handle_speak:99 | Error in mute_and_speak
Traceback (most recent call last):
  File "/opt/mycroft-core/mycroft/audio/speech.py", line 95, in handle_speak
    mute_and_speak(chunk, ident, listen)
  File "/opt/mycroft-core/mycroft/audio/speech.py", line 120, in mute_and_speak
    tts.playback.stop()
AttributeError: 'NoneType' object has no attribute 'playback'
2021-10-25 08:43:14.897 | ERROR    |  7494 | mycroft.audio.speech:handle_speak:99 | Error in mute_and_speak
Traceback (most recent call last):
  File "/opt/mycroft-core/mycroft/audio/speech.py", line 95, in handle_speak
    mute_and_speak(chunk, ident, listen)
  File "/opt/mycroft-core/mycroft/audio/speech.py", line 120, in mute_and_speak
    tts.playback.stop()
AttributeError: 'NoneType' object has no attribute 'playback'
2021-10-25 08:43:15.572 | ERROR    |  7494 | mycroft.audio.speech:handle_speak:99 | Error in mute_and_speak
Traceback (most recent call last):
  File "/opt/mycroft-core/mycroft/audio/speech.py", line 95, in handle_speak
    mute_and_speak(chunk, ident, listen)
  File "/opt/mycroft-core/mycroft/audio/speech.py", line 120, in mute_and_speak
    tts.playback.stop()
AttributeError: 'NoneType' object has no attribute 'playback'
2021-10-25 08:43:15.933 | ERROR    |  7494 | mycroft.audio.speech:handle_speak:99 | Error in mute_and_speak
Traceback (most recent call last):
  File "/opt/mycroft-core/mycroft/audio/speech.py", line 95, in handle_speak
    mute_and_speak(chunk, ident, listen)
  File "/opt/mycroft-core/mycroft/audio/speech.py", line 120, in mute_and_speak
    tts.playback.stop()
AttributeError: 'NoneType' object has no attribute 'playback'
2021-10-25 08:43:23.457 | ERROR    |  7494 | mycroft.audio.speech:handle_speak:99 | Error in mute_and_speak
Traceback (most recent call last):
  File "/opt/mycroft-core/mycroft/audio/speech.py", line 95, in handle_speak
    mute_and_speak(chunk, ident, listen)
  File "/opt/mycroft-core/mycroft/audio/speech.py", line 120, in mute_and_speak
    tts.playback.stop()
AttributeError: 'NoneType' object has no attribute 'playback'
2021-10-25 08:43:24.254 | ERROR    |  7494 | mycroft.audio.speech:handle_speak:99 | Error in mute_and_speak
Traceback (most recent call last):
  File "/opt/mycroft-core/mycroft/audio/speech.py", line 95, in handle_speak
    mute_and_speak(chunk, ident, listen)
  File "/opt/mycroft-core/mycroft/audio/speech.py", line 120, in mute_and_speak
    tts.playback.stop()
AttributeError: 'NoneType' object has no attribute 'playback'
2021-10-25 08:43:24.838 | ERROR    |  7494 | mycroft.audio.speech:handle_speak:99 | Error in mute_and_speak
Traceback (most recent call last):
  File "/opt/mycroft-core/mycroft/audio/speech.py", line 95, in handle_speak
    mute_and_speak(chunk, ident, listen)
  File "/opt/mycroft-core/mycroft/audio/speech.py", line 120, in mute_and_speak
    tts.playback.stop()
AttributeError: 'NoneType' object has no attribute 'playback'
Exception ignored in: <module 'threading' from '/opt/hostedtoolcache/Python/3.7.12/x64/lib/python3.7/threading.py'>
Traceback (most recent call last):
  File "/opt/hostedtoolcache/Python/3.7.12/x64/lib/python3.7/threading.py", line 1307, in _shutdown
    lock.acquire()
KeyboardInterrupt
