2021-10-22 08:25:37.878 | INFO     |  5757 | __main__:main:46 | Starting Audio Service
2021-10-22 08:25:37.879 | INFO     |  5757 | mycroft.messagebus.load_config:load_message_bus_config:33 | Loading message bus configs
2021-10-22 08:25:37.883 | INFO     |  5757 | mycroft_bus_client.client.client | Connected
2021-10-22 08:25:37.884 | INFO     |  5757 | mycroft.util.process_utils:start_message_bus_client:155 | Connected to messagebus
2021-10-22 08:25:37.888 | WARNING  |  5757 | mycroft.tts.tts:clear_cache:428 | This method is deprecated, use TextToSpeechCache.clear
2021-10-22 08:25:38.055 | ERROR    |  5757 | mycroft.tts.mimic_tts:validate_connection:226 | Mimic executable not found
2021-10-22 08:25:38.056 | ERROR    |  5757 | mycroft.tts.tts:create:625 | The TTS could not be loaded.
Traceback (most recent call last):
  File "/opt/mycroft-core/mycroft/tts/mimic_tts.py", line 221, in validate_connection
    subprocess.call([mimic_bin, '--version'])
  File "/opt/hostedtoolcache/Python/3.7.12/x64/lib/python3.7/subprocess.py", line 339, in call
    with Popen(*popenargs, **kwargs) as p:
  File "/opt/hostedtoolcache/Python/3.7.12/x64/lib/python3.7/subprocess.py", line 800, in __init__
    restore_signals, start_new_session)
  File "/opt/hostedtoolcache/Python/3.7.12/x64/lib/python3.7/subprocess.py", line 1465, in _execute_child
    executable = os.fsencode(executable)
  File "/opt/hostedtoolcache/Python/3.7.12/x64/lib/python3.7/os.py", line 812, in fsencode
    filename = fspath(filename)  # Does type-checking of `filename`.
TypeError: expected str, bytes or os.PathLike object, not NoneType

The above exception was the direct cause of the following exception:

Traceback (most recent call last):
  File "/opt/mycroft-core/mycroft/tts/tts.py", line 614, in create
    tts.validator.validate()
  File "/opt/mycroft-core/mycroft/tts/tts.py", line 500, in validate
    self.validate_connection()
  File "/opt/mycroft-core/mycroft/tts/mimic_tts.py", line 229, in validate_connection
    from err
Exception: Mimic was not found. Run install-mimic.sh to install it.
2021-10-22 08:25:38.110 | ERROR    |  5757 | __main__:on_error:37 | Audio service failed to launch (Exception('Mimic was not found. Run install-mimic.sh to install it.')).
2021-10-22 08:25:51.519 | ERROR    |  5757 | mycroft.audio.speech:handle_speak:99 | Error in mute_and_speak
Traceback (most recent call last):
  File "/opt/mycroft-core/mycroft/audio/speech.py", line 95, in handle_speak
    mute_and_speak(chunk, ident, listen)
  File "/opt/mycroft-core/mycroft/audio/speech.py", line 120, in mute_and_speak
    tts.playback.stop()
AttributeError: 'NoneType' object has no attribute 'playback'
2021-10-22 08:26:22.014 | ERROR    |  5757 | mycroft.audio.speech:handle_speak:99 | Error in mute_and_speak
Traceback (most recent call last):
  File "/opt/mycroft-core/mycroft/audio/speech.py", line 95, in handle_speak
    mute_and_speak(chunk, ident, listen)
  File "/opt/mycroft-core/mycroft/audio/speech.py", line 120, in mute_and_speak
    tts.playback.stop()
AttributeError: 'NoneType' object has no attribute 'playback'
2021-10-22 08:26:22.015 | ERROR    |  5757 | mycroft.audio.speech:handle_speak:99 | Error in mute_and_speak
Traceback (most recent call last):
  File "/opt/mycroft-core/mycroft/audio/speech.py", line 95, in handle_speak
    mute_and_speak(chunk, ident, listen)
  File "/opt/mycroft-core/mycroft/audio/speech.py", line 120, in mute_and_speak
    tts.playback.stop()
AttributeError: 'NoneType' object has no attribute 'playback'
2021-10-22 08:26:41.903 | ERROR    |  5757 | websocket | error from callback <bound method MessageBusClient.on_message of <mycroft.messagebus.client.client.MessageBusClient object at 0x7fd7feeb1ed0>>: cannot schedule new futures after interpreter shutdown
2021-10-22 08:26:41.903 | ERROR    |  5757 | websocket | error from callback <bound method MessageBusClient.on_message of <mycroft.messagebus.client.client.MessageBusClient object at 0x7fd7feeb1ed0>>: cannot schedule new futures after interpreter shutdown
2021-10-22 08:26:41.903 | ERROR    |  5757 | websocket | error from callback <bound method MessageBusClient.on_message of <mycroft.messagebus.client.client.MessageBusClient object at 0x7fd7feeb1ed0>>: cannot schedule new futures after interpreter shutdown
2021-10-22 08:26:41.904 | ERROR    |  5757 | websocket | error from callback <bound method MessageBusClient.on_message of <mycroft.messagebus.client.client.MessageBusClient object at 0x7fd7feeb1ed0>>: cannot schedule new futures after interpreter shutdown
2021-10-22 08:26:41.904 | ERROR    |  5757 | websocket | error from callback <bound method MessageBusClient.on_message of <mycroft.messagebus.client.client.MessageBusClient object at 0x7fd7feeb1ed0>>: cannot schedule new futures after interpreter shutdown
2021-10-22 08:26:41.904 | ERROR    |  5757 | websocket | error from callback <bound method MessageBusClient.on_message of <mycroft.messagebus.client.client.MessageBusClient object at 0x7fd7feeb1ed0>>: cannot schedule new futures after interpreter shutdown
2021-10-22 08:26:41.904 | ERROR    |  5757 | websocket | error from callback <bound method MessageBusClient.on_message of <mycroft.messagebus.client.client.MessageBusClient object at 0x7fd7feeb1ed0>>: cannot schedule new futures after interpreter shutdown
2021-10-22 08:26:41.905 | ERROR    |  5757 | websocket | error from callback <bound method MessageBusClient.on_message of <mycroft.messagebus.client.client.MessageBusClient object at 0x7fd7feeb1ed0>>: cannot schedule new futures after interpreter shutdown
2021-10-22 08:26:41.905 | ERROR    |  5757 | websocket | error from callback <bound method MessageBusClient.on_message of <mycroft.messagebus.client.client.MessageBusClient object at 0x7fd7feeb1ed0>>: cannot schedule new futures after interpreter shutdown
2021-10-22 08:26:41.905 | ERROR    |  5757 | websocket | error from callback <bound method MessageBusClient.on_message of <mycroft.messagebus.client.client.MessageBusClient object at 0x7fd7feeb1ed0>>: cannot schedule new futures after interpreter shutdown
2021-10-22 08:26:41.905 | ERROR    |  5757 | websocket | error from callback <bound method MessageBusClient.on_message of <mycroft.messagebus.client.client.MessageBusClient object at 0x7fd7feeb1ed0>>: cannot schedule new futures after interpreter shutdown
2021-10-22 08:26:41.905 | ERROR    |  5757 | websocket | error from callback <bound method MessageBusClient.on_message of <mycroft.messagebus.client.client.MessageBusClient object at 0x7fd7feeb1ed0>>: cannot schedule new futures after interpreter shutdown
2021-10-22 08:26:41.906 | ERROR    |  5757 | websocket | error from callback <bound method MessageBusClient.on_message of <mycroft.messagebus.client.client.MessageBusClient object at 0x7fd7feeb1ed0>>: cannot schedule new futures after interpreter shutdown
2021-10-22 08:26:41.906 | ERROR    |  5757 | websocket | error from callback <bound method MessageBusClient.on_message of <mycroft.messagebus.client.client.MessageBusClient object at 0x7fd7feeb1ed0>>: cannot schedule new futures after interpreter shutdown
2021-10-22 08:26:41.906 | ERROR    |  5757 | websocket | error from callback <bound method MessageBusClient.on_message of <mycroft.messagebus.client.client.MessageBusClient object at 0x7fd7feeb1ed0>>: cannot schedule new futures after interpreter shutdown
2021-10-22 08:26:41.906 | ERROR    |  5757 | websocket | error from callback <bound method MessageBusClient.on_message of <mycroft.messagebus.client.client.MessageBusClient object at 0x7fd7feeb1ed0>>: cannot schedule new futures after interpreter shutdown
2021-10-22 08:26:41.906 | ERROR    |  5757 | websocket | error from callback <bound method MessageBusClient.on_message of <mycroft.messagebus.client.client.MessageBusClient object at 0x7fd7feeb1ed0>>: cannot schedule new futures after interpreter shutdown
2021-10-22 08:26:41.906 | ERROR    |  5757 | websocket | error from callback <bound method MessageBusClient.on_message of <mycroft.messagebus.client.client.MessageBusClient object at 0x7fd7feeb1ed0>>: cannot schedule new futures after interpreter shutdown
2021-10-22 08:26:41.907 | ERROR    |  5757 | websocket | error from callback <bound method MessageBusClient.on_message of <mycroft.messagebus.client.client.MessageBusClient object at 0x7fd7feeb1ed0>>: cannot schedule new futures after interpreter shutdown
2021-10-22 08:26:41.907 | ERROR    |  5757 | websocket | error from callback <bound method MessageBusClient.on_message of <mycroft.messagebus.client.client.MessageBusClient object at 0x7fd7feeb1ed0>>: cannot schedule new futures after interpreter shutdown
2021-10-22 08:26:41.907 | ERROR    |  5757 | websocket | error from callback <bound method MessageBusClient.on_message of <mycroft.messagebus.client.client.MessageBusClient object at 0x7fd7feeb1ed0>>: cannot schedule new futures after shutdown
2021-10-22 08:26:41.908 | ERROR    |  5757 | websocket | error from callback <bound method MessageBusClient.on_message of <mycroft.messagebus.client.client.MessageBusClient object at 0x7fd7feeb1ed0>>: cannot schedule new futures after shutdown
2021-10-22 08:26:54.551 | INFO     |  7370 | __main__:main:46 | Starting Audio Service
2021-10-22 08:26:54.552 | INFO     |  7370 | mycroft.messagebus.load_config:load_message_bus_config:33 | Loading message bus configs
2021-10-22 08:26:54.555 | INFO     |  7370 | mycroft_bus_client.client.client | Connected
2021-10-22 08:26:54.556 | INFO     |  7370 | mycroft.util.process_utils:start_message_bus_client:155 | Connected to messagebus
2021-10-22 08:26:54.559 | WARNING  |  7370 | mycroft.tts.tts:clear_cache:428 | This method is deprecated, use TextToSpeechCache.clear
2021-10-22 08:26:54.723 | ERROR    |  7370 | mycroft.tts.mimic_tts:validate_connection:226 | Mimic executable not found
2021-10-22 08:26:54.724 | ERROR    |  7370 | mycroft.tts.tts:create:625 | The TTS could not be loaded.
Traceback (most recent call last):
  File "/opt/mycroft-core/mycroft/tts/mimic_tts.py", line 221, in validate_connection
    subprocess.call([mimic_bin, '--version'])
  File "/opt/hostedtoolcache/Python/3.7.12/x64/lib/python3.7/subprocess.py", line 339, in call
    with Popen(*popenargs, **kwargs) as p:
  File "/opt/hostedtoolcache/Python/3.7.12/x64/lib/python3.7/subprocess.py", line 800, in __init__
    restore_signals, start_new_session)
  File "/opt/hostedtoolcache/Python/3.7.12/x64/lib/python3.7/subprocess.py", line 1465, in _execute_child
    executable = os.fsencode(executable)
  File "/opt/hostedtoolcache/Python/3.7.12/x64/lib/python3.7/os.py", line 812, in fsencode
    filename = fspath(filename)  # Does type-checking of `filename`.
TypeError: expected str, bytes or os.PathLike object, not NoneType

The above exception was the direct cause of the following exception:

Traceback (most recent call last):
  File "/opt/mycroft-core/mycroft/tts/tts.py", line 614, in create
    tts.validator.validate()
  File "/opt/mycroft-core/mycroft/tts/tts.py", line 500, in validate
    self.validate_connection()
  File "/opt/mycroft-core/mycroft/tts/mimic_tts.py", line 229, in validate_connection
    from err
Exception: Mimic was not found. Run install-mimic.sh to install it.
2021-10-22 08:26:54.725 | ERROR    |  7370 | __main__:on_error:37 | Audio service failed to launch (Exception('Mimic was not found. Run install-mimic.sh to install it.')).
2021-10-22 08:26:56.049 | ERROR    |  7370 | mycroft.audio.speech:handle_speak:99 | Error in mute_and_speak
Traceback (most recent call last):
  File "/opt/mycroft-core/mycroft/audio/speech.py", line 95, in handle_speak
    mute_and_speak(chunk, ident, listen)
  File "/opt/mycroft-core/mycroft/audio/speech.py", line 120, in mute_and_speak
    tts.playback.stop()
AttributeError: 'NoneType' object has no attribute 'playback'
2021-10-22 08:26:56.434 | ERROR    |  7370 | mycroft.audio.speech:handle_speak:99 | Error in mute_and_speak
Traceback (most recent call last):
  File "/opt/mycroft-core/mycroft/audio/speech.py", line 95, in handle_speak
    mute_and_speak(chunk, ident, listen)
  File "/opt/mycroft-core/mycroft/audio/speech.py", line 120, in mute_and_speak
    tts.playback.stop()
AttributeError: 'NoneType' object has no attribute 'playback'
2021-10-22 08:26:56.831 | ERROR    |  7370 | mycroft.audio.speech:handle_speak:99 | Error in mute_and_speak
Traceback (most recent call last):
  File "/opt/mycroft-core/mycroft/audio/speech.py", line 95, in handle_speak
    mute_and_speak(chunk, ident, listen)
  File "/opt/mycroft-core/mycroft/audio/speech.py", line 120, in mute_and_speak
    tts.playback.stop()
AttributeError: 'NoneType' object has no attribute 'playback'
2021-10-22 08:26:57.456 | ERROR    |  7370 | mycroft.audio.speech:handle_speak:99 | Error in mute_and_speak
Traceback (most recent call last):
  File "/opt/mycroft-core/mycroft/audio/speech.py", line 95, in handle_speak
    mute_and_speak(chunk, ident, listen)
  File "/opt/mycroft-core/mycroft/audio/speech.py", line 120, in mute_and_speak
    tts.playback.stop()
AttributeError: 'NoneType' object has no attribute 'playback'
2021-10-22 08:27:02.381 | ERROR    |  7370 | mycroft.audio.speech:handle_speak:99 | Error in mute_and_speak
Traceback (most recent call last):
  File "/opt/mycroft-core/mycroft/audio/speech.py", line 95, in handle_speak
    mute_and_speak(chunk, ident, listen)
  File "/opt/mycroft-core/mycroft/audio/speech.py", line 120, in mute_and_speak
    tts.playback.stop()
AttributeError: 'NoneType' object has no attribute 'playback'
2021-10-22 08:27:06.445 | ERROR    |  7370 | mycroft.audio.speech:handle_speak:99 | Error in mute_and_speak
Traceback (most recent call last):
  File "/opt/mycroft-core/mycroft/audio/speech.py", line 95, in handle_speak
    mute_and_speak(chunk, ident, listen)
  File "/opt/mycroft-core/mycroft/audio/speech.py", line 120, in mute_and_speak
    tts.playback.stop()
AttributeError: 'NoneType' object has no attribute 'playback'
2021-10-22 08:27:06.859 | ERROR    |  7370 | mycroft.audio.speech:handle_speak:99 | Error in mute_and_speak
Traceback (most recent call last):
  File "/opt/mycroft-core/mycroft/audio/speech.py", line 95, in handle_speak
    mute_and_speak(chunk, ident, listen)
  File "/opt/mycroft-core/mycroft/audio/speech.py", line 120, in mute_and_speak
    tts.playback.stop()
AttributeError: 'NoneType' object has no attribute 'playback'
2021-10-22 08:27:07.245 | ERROR    |  7370 | mycroft.audio.speech:handle_speak:99 | Error in mute_and_speak
Traceback (most recent call last):
  File "/opt/mycroft-core/mycroft/audio/speech.py", line 95, in handle_speak
    mute_and_speak(chunk, ident, listen)
  File "/opt/mycroft-core/mycroft/audio/speech.py", line 120, in mute_and_speak
    tts.playback.stop()
AttributeError: 'NoneType' object has no attribute 'playback'
2021-10-22 08:27:07.805 | ERROR    |  7370 | mycroft.audio.speech:handle_speak:99 | Error in mute_and_speak
Traceback (most recent call last):
  File "/opt/mycroft-core/mycroft/audio/speech.py", line 95, in handle_speak
    mute_and_speak(chunk, ident, listen)
  File "/opt/mycroft-core/mycroft/audio/speech.py", line 120, in mute_and_speak
    tts.playback.stop()
AttributeError: 'NoneType' object has no attribute 'playback'
2021-10-22 08:27:08.547 | ERROR    |  7370 | mycroft.audio.speech:handle_speak:99 | Error in mute_and_speak
Traceback (most recent call last):
  File "/opt/mycroft-core/mycroft/audio/speech.py", line 95, in handle_speak
    mute_and_speak(chunk, ident, listen)
  File "/opt/mycroft-core/mycroft/audio/speech.py", line 120, in mute_and_speak
    tts.playback.stop()
AttributeError: 'NoneType' object has no attribute 'playback'
2021-10-22 08:27:09.628 | ERROR    |  7370 | mycroft.audio.speech:handle_speak:99 | Error in mute_and_speak
Traceback (most recent call last):
  File "/opt/mycroft-core/mycroft/audio/speech.py", line 95, in handle_speak
    mute_and_speak(chunk, ident, listen)
  File "/opt/mycroft-core/mycroft/audio/speech.py", line 120, in mute_and_speak
    tts.playback.stop()
AttributeError: 'NoneType' object has no attribute 'playback'
2021-10-22 08:27:16.147 | ERROR    |  7370 | mycroft.audio.speech:handle_speak:99 | Error in mute_and_speak
Traceback (most recent call last):
  File "/opt/mycroft-core/mycroft/audio/speech.py", line 95, in handle_speak
    mute_and_speak(chunk, ident, listen)
  File "/opt/mycroft-core/mycroft/audio/speech.py", line 120, in mute_and_speak
    tts.playback.stop()
AttributeError: 'NoneType' object has no attribute 'playback'
2021-10-22 08:27:16.948 | ERROR    |  7370 | mycroft.audio.speech:handle_speak:99 | Error in mute_and_speak
Traceback (most recent call last):
  File "/opt/mycroft-core/mycroft/audio/speech.py", line 95, in handle_speak
    mute_and_speak(chunk, ident, listen)
  File "/opt/mycroft-core/mycroft/audio/speech.py", line 120, in mute_and_speak
    tts.playback.stop()
AttributeError: 'NoneType' object has no attribute 'playback'
2021-10-22 08:27:17.484 | ERROR    |  7370 | mycroft.audio.speech:handle_speak:99 | Error in mute_and_speak
Traceback (most recent call last):
  File "/opt/mycroft-core/mycroft/audio/speech.py", line 95, in handle_speak
    mute_and_speak(chunk, ident, listen)
  File "/opt/mycroft-core/mycroft/audio/speech.py", line 120, in mute_and_speak
    tts.playback.stop()
AttributeError: 'NoneType' object has no attribute 'playback'
Exception ignored in: <module 'threading' from '/opt/hostedtoolcache/Python/3.7.12/x64/lib/python3.7/threading.py'>
Traceback (most recent call last):
  File "/opt/hostedtoolcache/Python/3.7.12/x64/lib/python3.7/threading.py", line 1307, in _shutdown
    lock.acquire()
KeyboardInterrupt
