2022-02-25 19:40:12.048 | INFO     |  4711 | __main__:create_enclosure:55 | Creating generic enclosure, platform='None'
2022-02-25 19:40:12.055 | INFO     |  4711 | mycroft.messagebus.load_config:load_message_bus_config:33 | Loading message bus configs
2022-02-25 19:40:12.062 | INFO     |  4711 | mycroft.client.enclosure.base:create_gui_service:473 | Starting message bus for GUI...
2022-02-25 19:40:12.065 | INFO     |  4711 | mycroft.client.enclosure.base:create_gui_service:483 | GUI Message bus started!
2022-02-25 19:40:12.066 | INFO     |  4711 | mycroft.enclosure.display_manager:init_display_manager_bus_connection:152 | Connecting display manager to messagebus
2022-02-25 19:40:12.066 | INFO     |  4711 | mycroft.messagebus.load_config:load_message_bus_config:33 | Loading message bus configs
2022-02-25 19:40:12.082 | INFO     |  4711 | mycroft_bus_client.client.client | Connected
2022-02-25 19:40:12.157 | INFO     |  4711 | mycroft_bus_client.client.client | Connected
2022-02-25 19:40:12.170 | INFO     |  4711 | mycroft.util.process_utils:start_message_bus_client:155 | Connected to messagebus
2022-02-25 19:40:12.170 | INFO     |  4711 | __main__:on_ready:26 | Enclosure started!
2022-02-25 19:42:16.893 | INFO     |  4711 | __main__:on_stopping:30 | Enclosure is shutting down...
2022-02-25 19:42:17.297 | ERROR    |  4711 | websocket | error from callback <bound method MessageBusClient.on_message of <mycroft.messagebus.client.client.MessageBusClient object at 0x7f855785ab10>>: cannot schedule new futures after shutdown
2022-02-25 19:42:17.297 | ERROR    |  4711 | mycroft_bus_client.client.client | === RuntimeError('cannot schedule new futures after shutdown') ===
Traceback (most recent call last):
  File "/opt/mycroft-core/.venv/lib/python3.7/site-packages/websocket/_app.py", line 407, in _callback
    callback(self, *args)
  File "/opt/mycroft-core/.venv/lib/python3.7/site-packages/mycroft_bus_client/client/client.py", line 182, in on_message
    self.emitter.emit('message', message)
  File "/opt/mycroft-core/.venv/lib/python3.7/site-packages/pyee/_base.py", line 113, in emit
    handled = self._call_handlers(event, args, kwargs)
  File "/opt/mycroft-core/.venv/lib/python3.7/site-packages/pyee/_base.py", line 96, in _call_handlers
    self._emit_run(f, args, kwargs)
  File "/opt/mycroft-core/.venv/lib/python3.7/site-packages/pyee/_executor.py", line 50, in _emit_run
    future = self._executor.submit(f, *args, **kwargs)
  File "/opt/hostedtoolcache/Python/3.7.12/x64/lib/python3.7/concurrent/futures/thread.py", line 163, in submit
    raise RuntimeError('cannot schedule new futures after shutdown')
RuntimeError: cannot schedule new futures after shutdown
2022-02-25 19:42:17.298 | ERROR    |  4711 | mycroft_bus_client.client.client | Exception closing websocket: RuntimeError('cannot schedule new futures after shutdown')
2022-02-25 19:42:17.298 | WARNING  |  4711 | mycroft_bus_client.client.client | Message Bus Client will reconnect in 5.0 seconds.
2022-02-25 19:42:22.306 | INFO     |  4711 | mycroft_bus_client.client.client | Connected
2022-02-25 19:42:22.306 | ERROR    |  4711 | websocket | error from callback <bound method MessageBusClient.on_message of <mycroft.messagebus.client.client.MessageBusClient object at 0x7f855785ab10>>: cannot schedule new futures after shutdown
2022-02-25 19:42:22.306 | ERROR    |  4711 | mycroft_bus_client.client.client | === RuntimeError('cannot schedule new futures after shutdown') ===
Traceback (most recent call last):
  File "/opt/mycroft-core/.venv/lib/python3.7/site-packages/mycroft_bus_client/client/client.py", line 154, in on_error
    self.emitter.emit('error', error)
  File "/opt/mycroft-core/.venv/lib/python3.7/site-packages/pyee/_base.py", line 116, in emit
    self._emit_handle_potential_error(event, args[0] if args else None)
  File "/opt/mycroft-core/.venv/lib/python3.7/site-packages/pyee/_base.py", line 86, in _emit_handle_potential_error
    raise error
  File "/opt/mycroft-core/.venv/lib/python3.7/site-packages/websocket/_app.py", line 407, in _callback
    callback(self, *args)
  File "/opt/mycroft-core/.venv/lib/python3.7/site-packages/mycroft_bus_client/client/client.py", line 182, in on_message
    self.emitter.emit('message', message)
  File "/opt/mycroft-core/.venv/lib/python3.7/site-packages/pyee/_base.py", line 113, in emit
    handled = self._call_handlers(event, args, kwargs)
  File "/opt/mycroft-core/.venv/lib/python3.7/site-packages/pyee/_base.py", line 96, in _call_handlers
    self._emit_run(f, args, kwargs)
  File "/opt/mycroft-core/.venv/lib/python3.7/site-packages/pyee/_executor.py", line 50, in _emit_run
    future = self._executor.submit(f, *args, **kwargs)
  File "/opt/hostedtoolcache/Python/3.7.12/x64/lib/python3.7/concurrent/futures/thread.py", line 163, in submit
    raise RuntimeError('cannot schedule new futures after shutdown')
RuntimeError: cannot schedule new futures after shutdown

During handling of the above exception, another exception occurred:

Traceback (most recent call last):
  File "/opt/mycroft-core/.venv/lib/python3.7/site-packages/websocket/_app.py", line 407, in _callback
    callback(self, *args)
  File "/opt/mycroft-core/.venv/lib/python3.7/site-packages/mycroft_bus_client/client/client.py", line 182, in on_message
    self.emitter.emit('message', message)
  File "/opt/mycroft-core/.venv/lib/python3.7/site-packages/pyee/_base.py", line 113, in emit
    handled = self._call_handlers(event, args, kwargs)
  File "/opt/mycroft-core/.venv/lib/python3.7/site-packages/pyee/_base.py", line 96, in _call_handlers
    self._emit_run(f, args, kwargs)
  File "/opt/mycroft-core/.venv/lib/python3.7/site-packages/pyee/_executor.py", line 50, in _emit_run
    future = self._executor.submit(f, *args, **kwargs)
  File "/opt/hostedtoolcache/Python/3.7.12/x64/lib/python3.7/concurrent/futures/thread.py", line 163, in submit
    raise RuntimeError('cannot schedule new futures after shutdown')
RuntimeError: cannot schedule new futures after shutdown
2022-02-25 19:42:22.307 | ERROR    |  4711 | mycroft_bus_client.client.client | Exception closing websocket: RuntimeError('cannot schedule new futures after shutdown')
2022-02-25 19:42:22.307 | WARNING  |  4711 | mycroft_bus_client.client.client | Message Bus Client will reconnect in 5.0 seconds.
