2021-10-25 08:26:58.657 | INFO     |  5782 | __main__:main:46 | Starting Audio Service
2021-10-25 08:26:58.658 | INFO     |  5782 | mycroft.messagebus.load_config:load_message_bus_config:33 | Loading message bus configs
2021-10-25 08:26:58.662 | INFO     |  5782 | mycroft_bus_client.client.client | Connected
2021-10-25 08:26:58.664 | INFO     |  5782 | mycroft.util.process_utils:start_message_bus_client:155 | Connected to messagebus
2021-10-25 08:26:58.667 | WARNING  |  5782 | mycroft.tts.tts:clear_cache:428 | This method is deprecated, use TextToSpeechCache.clear
2021-10-25 08:26:58.938 | ERROR    |  5782 | mycroft.tts.mimic_tts:validate_connection:226 | Mimic executable not found
2021-10-25 08:26:58.939 | ERROR    |  5782 | mycroft.tts.tts:create:625 | The TTS could not be loaded.
Traceback (most recent call last):
  File "/opt/mycroft-core/mycroft/tts/mimic_tts.py", line 221, in validate_connection
    subprocess.call([mimic_bin, '--version'])
  File "/opt/hostedtoolcache/Python/3.7.12/x64/lib/python3.7/subprocess.py", line 339, in call
    with Popen(*popenargs, **kwargs) as p:
  File "/opt/hostedtoolcache/Python/3.7.12/x64/lib/python3.7/subprocess.py", line 800, in __init__
    restore_signals, start_new_session)
  File "/opt/hostedtoolcache/Python/3.7.12/x64/lib/python3.7/subprocess.py", line 1465, in _execute_child
    executable = os.fsencode(executable)
  File "/opt/hostedtoolcache/Python/3.7.12/x64/lib/python3.7/os.py", line 812, in fsencode
    filename = fspath(filename)  # Does type-checking of `filename`.
TypeError: expected str, bytes or os.PathLike object, not NoneType

The above exception was the direct cause of the following exception:

Traceback (most recent call last):
  File "/opt/mycroft-core/mycroft/tts/tts.py", line 614, in create
    tts.validator.validate()
  File "/opt/mycroft-core/mycroft/tts/tts.py", line 500, in validate
    self.validate_connection()
  File "/opt/mycroft-core/mycroft/tts/mimic_tts.py", line 229, in validate_connection
    from err
Exception: Mimic was not found. Run install-mimic.sh to install it.
2021-10-25 08:26:58.960 | ERROR    |  5782 | __main__:on_error:37 | Audio service failed to launch (Exception('Mimic was not found. Run install-mimic.sh to install it.')).
2021-10-25 08:27:12.847 | ERROR    |  5782 | mycroft.audio.speech:handle_speak:99 | Error in mute_and_speak
Traceback (most recent call last):
  File "/opt/mycroft-core/mycroft/audio/speech.py", line 95, in handle_speak
    mute_and_speak(chunk, ident, listen)
  File "/opt/mycroft-core/mycroft/audio/speech.py", line 120, in mute_and_speak
    tts.playback.stop()
AttributeError: 'NoneType' object has no attribute 'playback'
2021-10-25 08:27:43.279 | ERROR    |  5782 | mycroft.audio.speech:handle_speak:99 | Error in mute_and_speak
Traceback (most recent call last):
  File "/opt/mycroft-core/mycroft/audio/speech.py", line 95, in handle_speak
    mute_and_speak(chunk, ident, listen)
  File "/opt/mycroft-core/mycroft/audio/speech.py", line 120, in mute_and_speak
    tts.playback.stop()
AttributeError: 'NoneType' object has no attribute 'playback'
2021-10-25 08:27:43.280 | ERROR    |  5782 | mycroft.audio.speech:handle_speak:99 | Error in mute_and_speak
Traceback (most recent call last):
  File "/opt/mycroft-core/mycroft/audio/speech.py", line 95, in handle_speak
    mute_and_speak(chunk, ident, listen)
  File "/opt/mycroft-core/mycroft/audio/speech.py", line 120, in mute_and_speak
    tts.playback.stop()
AttributeError: 'NoneType' object has no attribute 'playback'
2021-10-25 08:28:02.606 | ERROR    |  5782 | concurrent.futures | exception calling callback for <Future at 0x7fb729575a10 state=finished raised FileExistsError>
Traceback (most recent call last):
  File "/opt/hostedtoolcache/Python/3.7.12/x64/lib/python3.7/concurrent/futures/_base.py", line 324, in _invoke_callbacks
    callback(self)
  File "/opt/mycroft-core/.venv/lib/python3.7/site-packages/pyee/_executor.py", line 56, in _callback
    self.emit('error', exc)
  File "/opt/mycroft-core/.venv/lib/python3.7/site-packages/pyee/_base.py", line 116, in emit
    self._emit_handle_potential_error(event, args[0] if args else None)
  File "/opt/mycroft-core/.venv/lib/python3.7/site-packages/pyee/_base.py", line 86, in _emit_handle_potential_error
    raise error
  File "/opt/hostedtoolcache/Python/3.7.12/x64/lib/python3.7/concurrent/futures/thread.py", line 57, in run
    result = self.fn(*self.args, **self.kwargs)
  File "/opt/mycroft-core/mycroft/configuration/config.py", line 289, in updated
    Configuration.load_config_stack(cache=True)
  File "/opt/mycroft-core/mycroft/configuration/config.py", line 241, in load_config_stack
    configs.append(RemoteConf())
  File "/opt/mycroft-core/mycroft/configuration/config.py", line 132, in __init__
    cache = cache or join(xdg.BaseDirectory.save_cache_path('mycroft'),
  File "/opt/mycroft-core/.venv/lib/python3.7/site-packages/xdg/BaseDirectory.py", line 81, in save_cache_path
    os.makedirs(path)
  File "/opt/hostedtoolcache/Python/3.7.12/x64/lib/python3.7/os.py", line 223, in makedirs
    mkdir(name, mode)
FileExistsError: [Errno 17] File exists: '/home/runner/.cache/mycroft'
2021-10-25 08:28:13.615 | ERROR    |  5782 | mycroft.audio.speech:handle_speak:99 | Error in mute_and_speak
Traceback (most recent call last):
  File "/opt/mycroft-core/mycroft/audio/speech.py", line 95, in handle_speak
    mute_and_speak(chunk, ident, listen)
  File "/opt/mycroft-core/mycroft/audio/speech.py", line 120, in mute_and_speak
    tts.playback.stop()
AttributeError: 'NoneType' object has no attribute 'playback'
2021-10-25 08:28:13.615 | ERROR    |  5782 | mycroft.audio.speech:handle_speak:99 | Error in mute_and_speak
Traceback (most recent call last):
  File "/opt/mycroft-core/mycroft/audio/speech.py", line 95, in handle_speak
    mute_and_speak(chunk, ident, listen)
  File "/opt/mycroft-core/mycroft/audio/speech.py", line 120, in mute_and_speak
    tts.playback.stop()
AttributeError: 'NoneType' object has no attribute 'playback'
2021-10-25 08:28:13.616 | ERROR    |  5782 | mycroft.audio.speech:handle_speak:99 | Error in mute_and_speak
Traceback (most recent call last):
  File "/opt/mycroft-core/mycroft/audio/speech.py", line 95, in handle_speak
    mute_and_speak(chunk, ident, listen)
  File "/opt/mycroft-core/mycroft/audio/speech.py", line 120, in mute_and_speak
    tts.playback.stop()
AttributeError: 'NoneType' object has no attribute 'playback'
2021-10-25 08:28:13.617 | ERROR    |  5782 | mycroft.audio.speech:handle_speak:99 | Error in mute_and_speak
Traceback (most recent call last):
  File "/opt/mycroft-core/mycroft/audio/speech.py", line 95, in handle_speak
    mute_and_speak(chunk, ident, listen)
  File "/opt/mycroft-core/mycroft/audio/speech.py", line 120, in mute_and_speak
    tts.playback.stop()
AttributeError: 'NoneType' object has no attribute 'playback'
2021-10-25 08:28:13.617 | ERROR    |  5782 | mycroft.audio.speech:handle_speak:99 | Error in mute_and_speak
Traceback (most recent call last):
  File "/opt/mycroft-core/mycroft/audio/speech.py", line 95, in handle_speak
    mute_and_speak(chunk, ident, listen)
  File "/opt/mycroft-core/mycroft/audio/speech.py", line 120, in mute_and_speak
    tts.playback.stop()
AttributeError: 'NoneType' object has no attribute 'playback'
2021-10-25 08:28:13.617 | ERROR    |  5782 | mycroft.audio.speech:handle_speak:99 | Error in mute_and_speak
Traceback (most recent call last):
  File "/opt/mycroft-core/mycroft/audio/speech.py", line 95, in handle_speak
    mute_and_speak(chunk, ident, listen)
  File "/opt/mycroft-core/mycroft/audio/speech.py", line 120, in mute_and_speak
    tts.playback.stop()
AttributeError: 'NoneType' object has no attribute 'playback'
2021-10-25 08:28:13.618 | ERROR    |  5782 | mycroft.audio.speech:handle_speak:99 | Error in mute_and_speak
Traceback (most recent call last):
  File "/opt/mycroft-core/mycroft/audio/speech.py", line 95, in handle_speak
    mute_and_speak(chunk, ident, listen)
  File "/opt/mycroft-core/mycroft/audio/speech.py", line 120, in mute_and_speak
    tts.playback.stop()
AttributeError: 'NoneType' object has no attribute 'playback'
2021-10-25 08:28:24.329 | ERROR    |  5782 | mycroft.audio.speech:handle_speak:99 | Error in mute_and_speak
Traceback (most recent call last):
  File "/opt/mycroft-core/mycroft/audio/speech.py", line 95, in handle_speak
    mute_and_speak(chunk, ident, listen)
  File "/opt/mycroft-core/mycroft/audio/speech.py", line 120, in mute_and_speak
    tts.playback.stop()
AttributeError: 'NoneType' object has no attribute 'playback'
2021-10-25 08:28:26.681 | ERROR    |  5782 | websocket | error from callback <bound method MessageBusClient.on_message of <mycroft.messagebus.client.client.MessageBusClient object at 0x7fb729547fd0>>: cannot schedule new futures after interpreter shutdown
2021-10-25 08:28:26.682 | ERROR    |  5782 | websocket | error from callback <bound method MessageBusClient.on_message of <mycroft.messagebus.client.client.MessageBusClient object at 0x7fb729547fd0>>: cannot schedule new futures after interpreter shutdown
2021-10-25 08:28:26.682 | ERROR    |  5782 | websocket | error from callback <bound method MessageBusClient.on_message of <mycroft.messagebus.client.client.MessageBusClient object at 0x7fb729547fd0>>: cannot schedule new futures after interpreter shutdown
2021-10-25 08:28:26.682 | ERROR    |  5782 | websocket | error from callback <bound method MessageBusClient.on_message of <mycroft.messagebus.client.client.MessageBusClient object at 0x7fb729547fd0>>: cannot schedule new futures after interpreter shutdown
2021-10-25 08:28:26.682 | ERROR    |  5782 | websocket | error from callback <bound method MessageBusClient.on_message of <mycroft.messagebus.client.client.MessageBusClient object at 0x7fb729547fd0>>: cannot schedule new futures after interpreter shutdown
2021-10-25 08:28:26.683 | ERROR    |  5782 | websocket | error from callback <bound method MessageBusClient.on_message of <mycroft.messagebus.client.client.MessageBusClient object at 0x7fb729547fd0>>: cannot schedule new futures after shutdown
