2022-03-16 07:57:57.512 | INFO     |  4759 | __main__:main:46 | Starting Audio Service
2022-03-16 07:57:57.537 | INFO     |  4759 | mycroft.messagebus.load_config:load_message_bus_config:33 | Loading message bus configs
2022-03-16 07:57:57.547 | INFO     |  4759 | mycroft_bus_client.client.client | Connected
2022-03-16 07:57:57.554 | INFO     |  4759 | mycroft.util.process_utils:start_message_bus_client:155 | Connected to messagebus
2022-03-16 07:57:57.878 | ERROR    |  4759 | mycroft.tts.mimic_tts:validate_connection:224 | Mimic executable not found
2022-03-16 07:57:57.879 | ERROR    |  4759 | mycroft.tts.tts:create:722 | The TTS could not be loaded.
Traceback (most recent call last):
  File "/opt/mycroft-core/mycroft/tts/mimic_tts.py", line 219, in validate_connection
    subprocess.call([mimic_bin, '--version'])
  File "/opt/hostedtoolcache/Python/3.7.12/x64/lib/python3.7/subprocess.py", line 339, in call
    with Popen(*popenargs, **kwargs) as p:
  File "/opt/hostedtoolcache/Python/3.7.12/x64/lib/python3.7/subprocess.py", line 800, in __init__
    restore_signals, start_new_session)
  File "/opt/hostedtoolcache/Python/3.7.12/x64/lib/python3.7/subprocess.py", line 1465, in _execute_child
    executable = os.fsencode(executable)
  File "/opt/hostedtoolcache/Python/3.7.12/x64/lib/python3.7/os.py", line 812, in fsencode
    filename = fspath(filename)  # Does type-checking of `filename`.
TypeError: expected str, bytes or os.PathLike object, not NoneType

The above exception was the direct cause of the following exception:

Traceback (most recent call last):
  File "/opt/mycroft-core/mycroft/tts/tts.py", line 711, in create
    tts.validator.validate()
  File "/opt/mycroft-core/mycroft/tts/tts.py", line 599, in validate
    self.validate_connection()
  File "/opt/mycroft-core/mycroft/tts/mimic_tts.py", line 227, in validate_connection
    from err
Exception: Mimic was not found. Run install-mimic.sh to install it.
2022-03-16 07:57:57.895 | ERROR    |  4759 | __main__:on_error:37 | Audio service failed to launch (Exception('Mimic was not found. Run install-mimic.sh to install it.')).
2022-03-16 07:58:10.779 | ERROR    |  4759 | concurrent.futures | exception calling callback for <Future at 0x7fe379f554d0 state=finished raised AttributeError>
Traceback (most recent call last):
  File "/opt/hostedtoolcache/Python/3.7.12/x64/lib/python3.7/concurrent/futures/_base.py", line 324, in _invoke_callbacks
    callback(self)
  File "/opt/mycroft-core/.venv/lib/python3.7/site-packages/pyee/_executor.py", line 56, in _callback
    self.emit('error', exc)
  File "/opt/mycroft-core/.venv/lib/python3.7/site-packages/pyee/_base.py", line 116, in emit
    self._emit_handle_potential_error(event, args[0] if args else None)
  File "/opt/mycroft-core/.venv/lib/python3.7/site-packages/pyee/_base.py", line 86, in _emit_handle_potential_error
    raise error
  File "/opt/hostedtoolcache/Python/3.7.12/x64/lib/python3.7/concurrent/futures/thread.py", line 57, in run
    result = self.fn(*self.args, **self.kwargs)
  File "/opt/mycroft-core/mycroft/audio/speech.py", line 77, in handle_speak
    chunks = tts.preprocess_utterance(utterance)
AttributeError: 'NoneType' object has no attribute 'preprocess_utterance'
2022-03-16 07:58:41.374 | ERROR    |  4759 | concurrent.futures | exception calling callback for <Future at 0x7fe378ef61d0 state=finished raised AttributeError>
Traceback (most recent call last):
  File "/opt/hostedtoolcache/Python/3.7.12/x64/lib/python3.7/concurrent/futures/_base.py", line 324, in _invoke_callbacks
    callback(self)
  File "/opt/mycroft-core/.venv/lib/python3.7/site-packages/pyee/_executor.py", line 56, in _callback
    self.emit('error', exc)
  File "/opt/mycroft-core/.venv/lib/python3.7/site-packages/pyee/_base.py", line 116, in emit
    self._emit_handle_potential_error(event, args[0] if args else None)
  File "/opt/mycroft-core/.venv/lib/python3.7/site-packages/pyee/_base.py", line 86, in _emit_handle_potential_error
    raise error
  File "/opt/hostedtoolcache/Python/3.7.12/x64/lib/python3.7/concurrent/futures/thread.py", line 57, in run
    result = self.fn(*self.args, **self.kwargs)
  File "/opt/mycroft-core/mycroft/audio/speech.py", line 77, in handle_speak
    chunks = tts.preprocess_utterance(utterance)
AttributeError: 'NoneType' object has no attribute 'preprocess_utterance'
2022-03-16 07:59:11.413 | ERROR    |  4759 | concurrent.futures | exception calling callback for <Future at 0x7fe378ef6610 state=finished raised AttributeError>
Traceback (most recent call last):
  File "/opt/hostedtoolcache/Python/3.7.12/x64/lib/python3.7/concurrent/futures/_base.py", line 324, in _invoke_callbacks
    callback(self)
  File "/opt/mycroft-core/.venv/lib/python3.7/site-packages/pyee/_executor.py", line 56, in _callback
    self.emit('error', exc)
  File "/opt/mycroft-core/.venv/lib/python3.7/site-packages/pyee/_base.py", line 116, in emit
    self._emit_handle_potential_error(event, args[0] if args else None)
  File "/opt/mycroft-core/.venv/lib/python3.7/site-packages/pyee/_base.py", line 86, in _emit_handle_potential_error
    raise error
  File "/opt/hostedtoolcache/Python/3.7.12/x64/lib/python3.7/concurrent/futures/thread.py", line 57, in run
    result = self.fn(*self.args, **self.kwargs)
  File "/opt/mycroft-core/mycroft/audio/speech.py", line 77, in handle_speak
    chunks = tts.preprocess_utterance(utterance)
AttributeError: 'NoneType' object has no attribute 'preprocess_utterance'
2022-03-16 07:59:30.397 | ERROR    |  4759 | concurrent.futures | exception calling callback for <Future at 0x7fe38a2bf0d0 state=finished raised AttributeError>
Traceback (most recent call last):
  File "/opt/hostedtoolcache/Python/3.7.12/x64/lib/python3.7/concurrent/futures/_base.py", line 324, in _invoke_callbacks
    callback(self)
  File "/opt/mycroft-core/.venv/lib/python3.7/site-packages/pyee/_executor.py", line 56, in _callback
    self.emit('error', exc)
  File "/opt/mycroft-core/.venv/lib/python3.7/site-packages/pyee/_base.py", line 116, in emit
    self._emit_handle_potential_error(event, args[0] if args else None)
  File "/opt/mycroft-core/.venv/lib/python3.7/site-packages/pyee/_base.py", line 86, in _emit_handle_potential_error
    raise error
  File "/opt/hostedtoolcache/Python/3.7.12/x64/lib/python3.7/concurrent/futures/thread.py", line 57, in run
    result = self.fn(*self.args, **self.kwargs)
  File "/opt/mycroft-core/mycroft/audio/speech.py", line 77, in handle_speak
    chunks = tts.preprocess_utterance(utterance)
AttributeError: 'NoneType' object has no attribute 'preprocess_utterance'
2022-03-16 07:59:30.803 | ERROR    |  4759 | concurrent.futures | exception calling callback for <Future at 0x7fe38a2bea10 state=finished raised AttributeError>
Traceback (most recent call last):
  File "/opt/hostedtoolcache/Python/3.7.12/x64/lib/python3.7/concurrent/futures/_base.py", line 324, in _invoke_callbacks
    callback(self)
  File "/opt/mycroft-core/.venv/lib/python3.7/site-packages/pyee/_executor.py", line 56, in _callback
    self.emit('error', exc)
  File "/opt/mycroft-core/.venv/lib/python3.7/site-packages/pyee/_base.py", line 116, in emit
    self._emit_handle_potential_error(event, args[0] if args else None)
  File "/opt/mycroft-core/.venv/lib/python3.7/site-packages/pyee/_base.py", line 86, in _emit_handle_potential_error
    raise error
  File "/opt/hostedtoolcache/Python/3.7.12/x64/lib/python3.7/concurrent/futures/thread.py", line 57, in run
    result = self.fn(*self.args, **self.kwargs)
  File "/opt/mycroft-core/mycroft/audio/speech.py", line 77, in handle_speak
    chunks = tts.preprocess_utterance(utterance)
AttributeError: 'NoneType' object has no attribute 'preprocess_utterance'
2022-03-16 07:59:31.208 | ERROR    |  4759 | concurrent.futures | exception calling callback for <Future at 0x7fe38a2be390 state=finished raised AttributeError>
Traceback (most recent call last):
  File "/opt/hostedtoolcache/Python/3.7.12/x64/lib/python3.7/concurrent/futures/_base.py", line 324, in _invoke_callbacks
    callback(self)
  File "/opt/mycroft-core/.venv/lib/python3.7/site-packages/pyee/_executor.py", line 56, in _callback
    self.emit('error', exc)
  File "/opt/mycroft-core/.venv/lib/python3.7/site-packages/pyee/_base.py", line 116, in emit
    self._emit_handle_potential_error(event, args[0] if args else None)
  File "/opt/mycroft-core/.venv/lib/python3.7/site-packages/pyee/_base.py", line 86, in _emit_handle_potential_error
    raise error
  File "/opt/hostedtoolcache/Python/3.7.12/x64/lib/python3.7/concurrent/futures/thread.py", line 57, in run
    result = self.fn(*self.args, **self.kwargs)
  File "/opt/mycroft-core/mycroft/audio/speech.py", line 77, in handle_speak
    chunks = tts.preprocess_utterance(utterance)
AttributeError: 'NoneType' object has no attribute 'preprocess_utterance'
2022-03-16 07:59:31.610 | ERROR    |  4759 | concurrent.futures | exception calling callback for <Future at 0x7fe38a2b9e90 state=finished raised AttributeError>
Traceback (most recent call last):
  File "/opt/hostedtoolcache/Python/3.7.12/x64/lib/python3.7/concurrent/futures/_base.py", line 324, in _invoke_callbacks
    callback(self)
  File "/opt/mycroft-core/.venv/lib/python3.7/site-packages/pyee/_executor.py", line 56, in _callback
    self.emit('error', exc)
  File "/opt/mycroft-core/.venv/lib/python3.7/site-packages/pyee/_base.py", line 116, in emit
    self._emit_handle_potential_error(event, args[0] if args else None)
  File "/opt/mycroft-core/.venv/lib/python3.7/site-packages/pyee/_base.py", line 86, in _emit_handle_potential_error
    raise error
  File "/opt/hostedtoolcache/Python/3.7.12/x64/lib/python3.7/concurrent/futures/thread.py", line 57, in run
    result = self.fn(*self.args, **self.kwargs)
  File "/opt/mycroft-core/mycroft/audio/speech.py", line 77, in handle_speak
    chunks = tts.preprocess_utterance(utterance)
AttributeError: 'NoneType' object has no attribute 'preprocess_utterance'
2022-03-16 07:59:32.631 | ERROR    |  4759 | concurrent.futures | exception calling callback for <Future at 0x7fe38a2b9690 state=finished raised AttributeError>
Traceback (most recent call last):
  File "/opt/hostedtoolcache/Python/3.7.12/x64/lib/python3.7/concurrent/futures/_base.py", line 324, in _invoke_callbacks
    callback(self)
  File "/opt/mycroft-core/.venv/lib/python3.7/site-packages/pyee/_executor.py", line 56, in _callback
    self.emit('error', exc)
  File "/opt/mycroft-core/.venv/lib/python3.7/site-packages/pyee/_base.py", line 116, in emit
    self._emit_handle_potential_error(event, args[0] if args else None)
  File "/opt/mycroft-core/.venv/lib/python3.7/site-packages/pyee/_base.py", line 86, in _emit_handle_potential_error
    raise error
  File "/opt/hostedtoolcache/Python/3.7.12/x64/lib/python3.7/concurrent/futures/thread.py", line 57, in run
    result = self.fn(*self.args, **self.kwargs)
  File "/opt/mycroft-core/mycroft/audio/speech.py", line 77, in handle_speak
    chunks = tts.preprocess_utterance(utterance)
AttributeError: 'NoneType' object has no attribute 'preprocess_utterance'
2022-03-16 07:59:40.813 | ERROR    |  4759 | concurrent.futures | exception calling callback for <Future at 0x7fe38a2ce7d0 state=finished raised AttributeError>
Traceback (most recent call last):
  File "/opt/hostedtoolcache/Python/3.7.12/x64/lib/python3.7/concurrent/futures/_base.py", line 324, in _invoke_callbacks
    callback(self)
  File "/opt/mycroft-core/.venv/lib/python3.7/site-packages/pyee/_executor.py", line 56, in _callback
    self.emit('error', exc)
  File "/opt/mycroft-core/.venv/lib/python3.7/site-packages/pyee/_base.py", line 116, in emit
    self._emit_handle_potential_error(event, args[0] if args else None)
  File "/opt/mycroft-core/.venv/lib/python3.7/site-packages/pyee/_base.py", line 86, in _emit_handle_potential_error
    raise error
  File "/opt/hostedtoolcache/Python/3.7.12/x64/lib/python3.7/concurrent/futures/thread.py", line 57, in run
    result = self.fn(*self.args, **self.kwargs)
  File "/opt/mycroft-core/mycroft/audio/speech.py", line 77, in handle_speak
    chunks = tts.preprocess_utterance(utterance)
AttributeError: 'NoneType' object has no attribute 'preprocess_utterance'
2022-03-16 07:59:41.245 | ERROR    |  4759 | concurrent.futures | exception calling callback for <Future at 0x7fe378f1ca10 state=finished raised AttributeError>
Traceback (most recent call last):
  File "/opt/hostedtoolcache/Python/3.7.12/x64/lib/python3.7/concurrent/futures/_base.py", line 324, in _invoke_callbacks
    callback(self)
  File "/opt/mycroft-core/.venv/lib/python3.7/site-packages/pyee/_executor.py", line 56, in _callback
    self.emit('error', exc)
  File "/opt/mycroft-core/.venv/lib/python3.7/site-packages/pyee/_base.py", line 116, in emit
    self._emit_handle_potential_error(event, args[0] if args else None)
  File "/opt/mycroft-core/.venv/lib/python3.7/site-packages/pyee/_base.py", line 86, in _emit_handle_potential_error
    raise error
  File "/opt/hostedtoolcache/Python/3.7.12/x64/lib/python3.7/concurrent/futures/thread.py", line 57, in run
    result = self.fn(*self.args, **self.kwargs)
  File "/opt/mycroft-core/mycroft/audio/speech.py", line 77, in handle_speak
    chunks = tts.preprocess_utterance(utterance)
AttributeError: 'NoneType' object has no attribute 'preprocess_utterance'
2022-03-16 07:59:41.649 | ERROR    |  4759 | concurrent.futures | exception calling callback for <Future at 0x7fe378ea71d0 state=finished raised AttributeError>
Traceback (most recent call last):
  File "/opt/hostedtoolcache/Python/3.7.12/x64/lib/python3.7/concurrent/futures/_base.py", line 324, in _invoke_callbacks
    callback(self)
  File "/opt/mycroft-core/.venv/lib/python3.7/site-packages/pyee/_executor.py", line 56, in _callback
    self.emit('error', exc)
  File "/opt/mycroft-core/.venv/lib/python3.7/site-packages/pyee/_base.py", line 116, in emit
    self._emit_handle_potential_error(event, args[0] if args else None)
  File "/opt/mycroft-core/.venv/lib/python3.7/site-packages/pyee/_base.py", line 86, in _emit_handle_potential_error
    raise error
  File "/opt/hostedtoolcache/Python/3.7.12/x64/lib/python3.7/concurrent/futures/thread.py", line 57, in run
    result = self.fn(*self.args, **self.kwargs)
  File "/opt/mycroft-core/mycroft/audio/speech.py", line 77, in handle_speak
    chunks = tts.preprocess_utterance(utterance)
AttributeError: 'NoneType' object has no attribute 'preprocess_utterance'
2022-03-16 07:59:42.013 | ERROR    |  4759 | concurrent.futures | exception calling callback for <Future at 0x7fe378ea7690 state=finished raised AttributeError>
Traceback (most recent call last):
  File "/opt/hostedtoolcache/Python/3.7.12/x64/lib/python3.7/concurrent/futures/_base.py", line 324, in _invoke_callbacks
    callback(self)
  File "/opt/mycroft-core/.venv/lib/python3.7/site-packages/pyee/_executor.py", line 56, in _callback
    self.emit('error', exc)
  File "/opt/mycroft-core/.venv/lib/python3.7/site-packages/pyee/_base.py", line 116, in emit
    self._emit_handle_potential_error(event, args[0] if args else None)
  File "/opt/mycroft-core/.venv/lib/python3.7/site-packages/pyee/_base.py", line 86, in _emit_handle_potential_error
    raise error
  File "/opt/hostedtoolcache/Python/3.7.12/x64/lib/python3.7/concurrent/futures/thread.py", line 57, in run
    result = self.fn(*self.args, **self.kwargs)
  File "/opt/mycroft-core/mycroft/audio/speech.py", line 77, in handle_speak
    chunks = tts.preprocess_utterance(utterance)
AttributeError: 'NoneType' object has no attribute 'preprocess_utterance'
2022-03-16 07:59:42.668 | ERROR    |  4759 | concurrent.futures | exception calling callback for <Future at 0x7fe378ea7e50 state=finished raised AttributeError>
Traceback (most recent call last):
  File "/opt/hostedtoolcache/Python/3.7.12/x64/lib/python3.7/concurrent/futures/_base.py", line 324, in _invoke_callbacks
    callback(self)
  File "/opt/mycroft-core/.venv/lib/python3.7/site-packages/pyee/_executor.py", line 56, in _callback
    self.emit('error', exc)
  File "/opt/mycroft-core/.venv/lib/python3.7/site-packages/pyee/_base.py", line 116, in emit
    self._emit_handle_potential_error(event, args[0] if args else None)
  File "/opt/mycroft-core/.venv/lib/python3.7/site-packages/pyee/_base.py", line 86, in _emit_handle_potential_error
    raise error
  File "/opt/hostedtoolcache/Python/3.7.12/x64/lib/python3.7/concurrent/futures/thread.py", line 57, in run
    result = self.fn(*self.args, **self.kwargs)
  File "/opt/mycroft-core/mycroft/audio/speech.py", line 77, in handle_speak
    chunks = tts.preprocess_utterance(utterance)
AttributeError: 'NoneType' object has no attribute 'preprocess_utterance'
2022-03-16 07:59:43.058 | ERROR    |  4759 | concurrent.futures | exception calling callback for <Future at 0x7fe378eaa1d0 state=finished raised AttributeError>
Traceback (most recent call last):
  File "/opt/hostedtoolcache/Python/3.7.12/x64/lib/python3.7/concurrent/futures/_base.py", line 324, in _invoke_callbacks
    callback(self)
  File "/opt/mycroft-core/.venv/lib/python3.7/site-packages/pyee/_executor.py", line 56, in _callback
    self.emit('error', exc)
  File "/opt/mycroft-core/.venv/lib/python3.7/site-packages/pyee/_base.py", line 116, in emit
    self._emit_handle_potential_error(event, args[0] if args else None)
  File "/opt/mycroft-core/.venv/lib/python3.7/site-packages/pyee/_base.py", line 86, in _emit_handle_potential_error
    raise error
  File "/opt/hostedtoolcache/Python/3.7.12/x64/lib/python3.7/concurrent/futures/thread.py", line 57, in run
    result = self.fn(*self.args, **self.kwargs)
  File "/opt/mycroft-core/mycroft/audio/speech.py", line 77, in handle_speak
    chunks = tts.preprocess_utterance(utterance)
AttributeError: 'NoneType' object has no attribute 'preprocess_utterance'
2022-03-16 07:59:50.466 | ERROR    |  4759 | concurrent.futures | exception calling callback for <Future at 0x7fe378eaa910 state=finished raised AttributeError>
Traceback (most recent call last):
  File "/opt/hostedtoolcache/Python/3.7.12/x64/lib/python3.7/concurrent/futures/_base.py", line 324, in _invoke_callbacks
    callback(self)
  File "/opt/mycroft-core/.venv/lib/python3.7/site-packages/pyee/_executor.py", line 56, in _callback
    self.emit('error', exc)
  File "/opt/mycroft-core/.venv/lib/python3.7/site-packages/pyee/_base.py", line 116, in emit
    self._emit_handle_potential_error(event, args[0] if args else None)
  File "/opt/mycroft-core/.venv/lib/python3.7/site-packages/pyee/_base.py", line 86, in _emit_handle_potential_error
    raise error
  File "/opt/hostedtoolcache/Python/3.7.12/x64/lib/python3.7/concurrent/futures/thread.py", line 57, in run
    result = self.fn(*self.args, **self.kwargs)
  File "/opt/mycroft-core/mycroft/audio/speech.py", line 77, in handle_speak
    chunks = tts.preprocess_utterance(utterance)
AttributeError: 'NoneType' object has no attribute 'preprocess_utterance'
2022-03-16 07:59:51.343 | ERROR    |  4759 | concurrent.futures | exception calling callback for <Future at 0x7fe378eaae90 state=finished raised AttributeError>
Traceback (most recent call last):
  File "/opt/hostedtoolcache/Python/3.7.12/x64/lib/python3.7/concurrent/futures/_base.py", line 324, in _invoke_callbacks
    callback(self)
  File "/opt/mycroft-core/.venv/lib/python3.7/site-packages/pyee/_executor.py", line 56, in _callback
    self.emit('error', exc)
  File "/opt/mycroft-core/.venv/lib/python3.7/site-packages/pyee/_base.py", line 116, in emit
    self._emit_handle_potential_error(event, args[0] if args else None)
  File "/opt/mycroft-core/.venv/lib/python3.7/site-packages/pyee/_base.py", line 86, in _emit_handle_potential_error
    raise error
  File "/opt/hostedtoolcache/Python/3.7.12/x64/lib/python3.7/concurrent/futures/thread.py", line 57, in run
    result = self.fn(*self.args, **self.kwargs)
  File "/opt/mycroft-core/mycroft/audio/speech.py", line 77, in handle_speak
    chunks = tts.preprocess_utterance(utterance)
AttributeError: 'NoneType' object has no attribute 'preprocess_utterance'
2022-03-16 07:59:51.862 | ERROR    |  4759 | concurrent.futures | exception calling callback for <Future at 0x7fe378eb1310 state=finished raised AttributeError>
Traceback (most recent call last):
  File "/opt/hostedtoolcache/Python/3.7.12/x64/lib/python3.7/concurrent/futures/_base.py", line 324, in _invoke_callbacks
    callback(self)
  File "/opt/mycroft-core/.venv/lib/python3.7/site-packages/pyee/_executor.py", line 56, in _callback
    self.emit('error', exc)
  File "/opt/mycroft-core/.venv/lib/python3.7/site-packages/pyee/_base.py", line 116, in emit
    self._emit_handle_potential_error(event, args[0] if args else None)
  File "/opt/mycroft-core/.venv/lib/python3.7/site-packages/pyee/_base.py", line 86, in _emit_handle_potential_error
    raise error
  File "/opt/hostedtoolcache/Python/3.7.12/x64/lib/python3.7/concurrent/futures/thread.py", line 57, in run
    result = self.fn(*self.args, **self.kwargs)
  File "/opt/mycroft-core/mycroft/audio/speech.py", line 77, in handle_speak
    chunks = tts.preprocess_utterance(utterance)
AttributeError: 'NoneType' object has no attribute 'preprocess_utterance'
2022-03-16 07:59:52.380 | ERROR    |  4759 | concurrent.futures | exception calling callback for <Future at 0x7fe378eb17d0 state=finished raised AttributeError>
Traceback (most recent call last):
  File "/opt/hostedtoolcache/Python/3.7.12/x64/lib/python3.7/concurrent/futures/_base.py", line 324, in _invoke_callbacks
    callback(self)
  File "/opt/mycroft-core/.venv/lib/python3.7/site-packages/pyee/_executor.py", line 56, in _callback
    self.emit('error', exc)
  File "/opt/mycroft-core/.venv/lib/python3.7/site-packages/pyee/_base.py", line 116, in emit
    self._emit_handle_potential_error(event, args[0] if args else None)
  File "/opt/mycroft-core/.venv/lib/python3.7/site-packages/pyee/_base.py", line 86, in _emit_handle_potential_error
    raise error
  File "/opt/hostedtoolcache/Python/3.7.12/x64/lib/python3.7/concurrent/futures/thread.py", line 57, in run
    result = self.fn(*self.args, **self.kwargs)
  File "/opt/mycroft-core/mycroft/audio/speech.py", line 77, in handle_speak
    chunks = tts.preprocess_utterance(utterance)
AttributeError: 'NoneType' object has no attribute 'preprocess_utterance'
2022-03-16 08:00:02.556 | ERROR    |  4759 | concurrent.futures | exception calling callback for <Future at 0x7fe378eb1cd0 state=finished raised AttributeError>
Traceback (most recent call last):
  File "/opt/hostedtoolcache/Python/3.7.12/x64/lib/python3.7/concurrent/futures/_base.py", line 324, in _invoke_callbacks
    callback(self)
  File "/opt/mycroft-core/.venv/lib/python3.7/site-packages/pyee/_executor.py", line 56, in _callback
    self.emit('error', exc)
  File "/opt/mycroft-core/.venv/lib/python3.7/site-packages/pyee/_base.py", line 116, in emit
    self._emit_handle_potential_error(event, args[0] if args else None)
  File "/opt/mycroft-core/.venv/lib/python3.7/site-packages/pyee/_base.py", line 86, in _emit_handle_potential_error
    raise error
  File "/opt/hostedtoolcache/Python/3.7.12/x64/lib/python3.7/concurrent/futures/thread.py", line 57, in run
    result = self.fn(*self.args, **self.kwargs)
  File "/opt/mycroft-core/mycroft/audio/speech.py", line 77, in handle_speak
    chunks = tts.preprocess_utterance(utterance)
AttributeError: 'NoneType' object has no attribute 'preprocess_utterance'
Exception ignored in: <module 'threading' from '/opt/hostedtoolcache/Python/3.7.12/x64/lib/python3.7/threading.py'>
Traceback (most recent call last):
  File "/opt/hostedtoolcache/Python/3.7.12/x64/lib/python3.7/threading.py", line 1307, in _shutdown
    lock.acquire()
KeyboardInterrupt
