2022-03-16 06:26:00.017 | INFO     |  4741 | __main__:create_enclosure:55 | Creating generic enclosure, platform='None'
2022-03-16 06:26:00.031 | INFO     |  4741 | mycroft.messagebus.load_config:load_message_bus_config:33 | Loading message bus configs
2022-03-16 06:26:00.033 | INFO     |  4741 | mycroft.client.enclosure.base:create_gui_service:473 | Starting message bus for GUI...
2022-03-16 06:26:00.050 | INFO     |  4741 | mycroft.client.enclosure.base:create_gui_service:483 | GUI Message bus started!
2022-03-16 06:26:00.050 | INFO     |  4741 | mycroft.enclosure.display_manager:init_display_manager_bus_connection:152 | Connecting display manager to messagebus
2022-03-16 06:26:00.051 | INFO     |  4741 | mycroft.messagebus.load_config:load_message_bus_config:33 | Loading message bus configs
2022-03-16 06:26:00.076 | ERROR    |  4741 | mycroft_bus_client.client.client | === ConnectionRefusedError(111, 'Connection refused') ===
Traceback (most recent call last):
  File "/opt/mycroft-core/.venv/lib/python3.7/site-packages/websocket/_app.py", line 318, in run_forever
    proxy_type=proxy_type)
  File "/opt/mycroft-core/.venv/lib/python3.7/site-packages/websocket/_core.py", line 250, in connect
    options.pop('socket', None))
  File "/opt/mycroft-core/.venv/lib/python3.7/site-packages/websocket/_http.py", line 130, in connect
    sock = _open_socket(addrinfo_list, options.sockopt, options.timeout)
  File "/opt/mycroft-core/.venv/lib/python3.7/site-packages/websocket/_http.py", line 208, in _open_socket
    raise err
  File "/opt/mycroft-core/.venv/lib/python3.7/site-packages/websocket/_http.py", line 185, in _open_socket
    sock.connect(address)
ConnectionRefusedError: [Errno 111] Connection refused
2022-03-16 06:26:00.076 | ERROR    |  4741 | mycroft_bus_client.client.client | Exception closing websocket: ConnectionRefusedError(111, 'Connection refused')
2022-03-16 06:26:00.077 | WARNING  |  4741 | mycroft_bus_client.client.client | Message Bus Client will reconnect in 5.0 seconds.
2022-03-16 06:26:00.126 | ERROR    |  4741 | mycroft_bus_client.client.client | === ConnectionRefusedError(111, 'Connection refused') ===
Traceback (most recent call last):
  File "/opt/mycroft-core/.venv/lib/python3.7/site-packages/websocket/_app.py", line 318, in run_forever
    proxy_type=proxy_type)
  File "/opt/mycroft-core/.venv/lib/python3.7/site-packages/websocket/_core.py", line 250, in connect
    options.pop('socket', None))
  File "/opt/mycroft-core/.venv/lib/python3.7/site-packages/websocket/_http.py", line 130, in connect
    sock = _open_socket(addrinfo_list, options.sockopt, options.timeout)
  File "/opt/mycroft-core/.venv/lib/python3.7/site-packages/websocket/_http.py", line 208, in _open_socket
    raise err
  File "/opt/mycroft-core/.venv/lib/python3.7/site-packages/websocket/_http.py", line 185, in _open_socket
    sock.connect(address)
ConnectionRefusedError: [Errno 111] Connection refused
2022-03-16 06:26:00.127 | ERROR    |  4741 | mycroft_bus_client.client.client | Exception closing websocket: ConnectionRefusedError(111, 'Connection refused')
2022-03-16 06:26:00.127 | WARNING  |  4741 | mycroft_bus_client.client.client | Message Bus Client will reconnect in 5.0 seconds.
2022-03-16 06:26:05.082 | INFO     |  4741 | mycroft_bus_client.client.client | Connected
2022-03-16 06:26:05.134 | INFO     |  4741 | mycroft_bus_client.client.client | Connected
2022-03-16 06:26:05.141 | INFO     |  4741 | mycroft.util.process_utils:start_message_bus_client:155 | Connected to messagebus
2022-03-16 06:26:05.142 | INFO     |  4741 | __main__:on_ready:26 | Enclosure started!
2022-03-16 06:27:39.357 | INFO     |  4741 | __main__:on_stopping:30 | Enclosure is shutting down...
2022-03-16 06:27:43.814 | ERROR    |  4741 | websocket | error from callback <bound method MessageBusClient.on_message of <mycroft.messagebus.client.client.MessageBusClient object at 0x7fcb9b5d1490>>: cannot schedule new futures after shutdown
2022-03-16 06:27:43.814 | ERROR    |  4741 | mycroft_bus_client.client.client | === RuntimeError('cannot schedule new futures after shutdown') ===
Traceback (most recent call last):
  File "/opt/mycroft-core/.venv/lib/python3.7/site-packages/mycroft_bus_client/client/client.py", line 154, in on_error
    self.emitter.emit('error', error)
  File "/opt/mycroft-core/.venv/lib/python3.7/site-packages/pyee/_base.py", line 116, in emit
    self._emit_handle_potential_error(event, args[0] if args else None)
  File "/opt/mycroft-core/.venv/lib/python3.7/site-packages/pyee/_base.py", line 86, in _emit_handle_potential_error
    raise error
  File "/opt/mycroft-core/.venv/lib/python3.7/site-packages/websocket/_app.py", line 318, in run_forever
    proxy_type=proxy_type)
  File "/opt/mycroft-core/.venv/lib/python3.7/site-packages/websocket/_core.py", line 250, in connect
    options.pop('socket', None))
  File "/opt/mycroft-core/.venv/lib/python3.7/site-packages/websocket/_http.py", line 130, in connect
    sock = _open_socket(addrinfo_list, options.sockopt, options.timeout)
  File "/opt/mycroft-core/.venv/lib/python3.7/site-packages/websocket/_http.py", line 208, in _open_socket
    raise err
  File "/opt/mycroft-core/.venv/lib/python3.7/site-packages/websocket/_http.py", line 185, in _open_socket
    sock.connect(address)
ConnectionRefusedError: [Errno 111] Connection refused

During handling of the above exception, another exception occurred:

Traceback (most recent call last):
  File "/opt/mycroft-core/.venv/lib/python3.7/site-packages/websocket/_app.py", line 407, in _callback
    callback(self, *args)
  File "/opt/mycroft-core/.venv/lib/python3.7/site-packages/mycroft_bus_client/client/client.py", line 182, in on_message
    self.emitter.emit('message', message)
  File "/opt/mycroft-core/.venv/lib/python3.7/site-packages/pyee/_base.py", line 113, in emit
    handled = self._call_handlers(event, args, kwargs)
  File "/opt/mycroft-core/.venv/lib/python3.7/site-packages/pyee/_base.py", line 96, in _call_handlers
    self._emit_run(f, args, kwargs)
  File "/opt/mycroft-core/.venv/lib/python3.7/site-packages/pyee/_executor.py", line 50, in _emit_run
    future = self._executor.submit(f, *args, **kwargs)
  File "/opt/hostedtoolcache/Python/3.7.12/x64/lib/python3.7/concurrent/futures/thread.py", line 163, in submit
    raise RuntimeError('cannot schedule new futures after shutdown')
RuntimeError: cannot schedule new futures after shutdown
2022-03-16 06:27:43.815 | ERROR    |  4741 | mycroft_bus_client.client.client | Exception closing websocket: RuntimeError('cannot schedule new futures after shutdown')
2022-03-16 06:27:43.815 | WARNING  |  4741 | mycroft_bus_client.client.client | Message Bus Client will reconnect in 5.0 seconds.
