2022-03-28 09:19:42.313 | INFO     |  4683 | __main__:main:46 | Starting Audio Service
2022-03-28 09:19:42.321 | INFO     |  4683 | mycroft.messagebus.load_config:load_message_bus_config:33 | Loading message bus configs
2022-03-28 09:19:42.325 | INFO     |  4683 | mycroft_bus_client.client.client | Connected
2022-03-28 09:19:42.332 | INFO     |  4683 | mycroft.util.process_utils:start_message_bus_client:155 | Connected to messagebus
2022-03-28 09:19:43.414 | ERROR    |  4683 | mycroft.tts.mimic_tts:validate_connection:224 | Mimic executable not found
2022-03-28 09:19:43.415 | ERROR    |  4683 | mycroft.tts.tts:create:722 | The TTS could not be loaded.
Traceback (most recent call last):
  File "/opt/mycroft-core/mycroft/tts/mimic_tts.py", line 219, in validate_connection
    subprocess.call([mimic_bin, '--version'])
  File "/opt/hostedtoolcache/Python/3.7.12/x64/lib/python3.7/subprocess.py", line 339, in call
    with Popen(*popenargs, **kwargs) as p:
  File "/opt/hostedtoolcache/Python/3.7.12/x64/lib/python3.7/subprocess.py", line 800, in __init__
    restore_signals, start_new_session)
  File "/opt/hostedtoolcache/Python/3.7.12/x64/lib/python3.7/subprocess.py", line 1465, in _execute_child
    executable = os.fsencode(executable)
  File "/opt/hostedtoolcache/Python/3.7.12/x64/lib/python3.7/os.py", line 812, in fsencode
    filename = fspath(filename)  # Does type-checking of `filename`.
TypeError: expected str, bytes or os.PathLike object, not NoneType

The above exception was the direct cause of the following exception:

Traceback (most recent call last):
  File "/opt/mycroft-core/mycroft/tts/tts.py", line 711, in create
    tts.validator.validate()
  File "/opt/mycroft-core/mycroft/tts/tts.py", line 599, in validate
    self.validate_connection()
  File "/opt/mycroft-core/mycroft/tts/mimic_tts.py", line 227, in validate_connection
    from err
Exception: Mimic was not found. Run install-mimic.sh to install it.
2022-03-28 09:19:43.510 | ERROR    |  4683 | __main__:on_error:37 | Audio service failed to launch (Exception('Mimic was not found. Run install-mimic.sh to install it.')).
2022-03-28 09:19:55.878 | ERROR    |  4683 | concurrent.futures | exception calling callback for <Future at 0x7f2f30d655d0 state=finished raised AttributeError>
Traceback (most recent call last):
  File "/opt/hostedtoolcache/Python/3.7.12/x64/lib/python3.7/concurrent/futures/_base.py", line 324, in _invoke_callbacks
    callback(self)
  File "/opt/mycroft-core/.venv/lib/python3.7/site-packages/pyee/_executor.py", line 56, in _callback
    self.emit('error', exc)
  File "/opt/mycroft-core/.venv/lib/python3.7/site-packages/pyee/_base.py", line 116, in emit
    self._emit_handle_potential_error(event, args[0] if args else None)
  File "/opt/mycroft-core/.venv/lib/python3.7/site-packages/pyee/_base.py", line 86, in _emit_handle_potential_error
    raise error
  File "/opt/hostedtoolcache/Python/3.7.12/x64/lib/python3.7/concurrent/futures/thread.py", line 57, in run
    result = self.fn(*self.args, **self.kwargs)
  File "/opt/mycroft-core/mycroft/audio/speech.py", line 77, in handle_speak
    chunks = tts.preprocess_utterance(utterance)
AttributeError: 'NoneType' object has no attribute 'preprocess_utterance'
2022-03-28 09:20:26.383 | ERROR    |  4683 | concurrent.futures | exception calling callback for <Future at 0x7f2f30d8a590 state=finished raised AttributeError>
Traceback (most recent call last):
  File "/opt/hostedtoolcache/Python/3.7.12/x64/lib/python3.7/concurrent/futures/_base.py", line 324, in _invoke_callbacks
    callback(self)
  File "/opt/mycroft-core/.venv/lib/python3.7/site-packages/pyee/_executor.py", line 56, in _callback
    self.emit('error', exc)
  File "/opt/mycroft-core/.venv/lib/python3.7/site-packages/pyee/_base.py", line 116, in emit
    self._emit_handle_potential_error(event, args[0] if args else None)
  File "/opt/mycroft-core/.venv/lib/python3.7/site-packages/pyee/_base.py", line 86, in _emit_handle_potential_error
    raise error
  File "/opt/hostedtoolcache/Python/3.7.12/x64/lib/python3.7/concurrent/futures/thread.py", line 57, in run
    result = self.fn(*self.args, **self.kwargs)
  File "/opt/mycroft-core/mycroft/audio/speech.py", line 77, in handle_speak
    chunks = tts.preprocess_utterance(utterance)
AttributeError: 'NoneType' object has no attribute 'preprocess_utterance'
2022-03-28 09:20:56.416 | ERROR    |  4683 | concurrent.futures | exception calling callback for <Future at 0x7f2f30d8a9d0 state=finished raised AttributeError>
Traceback (most recent call last):
  File "/opt/hostedtoolcache/Python/3.7.12/x64/lib/python3.7/concurrent/futures/_base.py", line 324, in _invoke_callbacks
    callback(self)
  File "/opt/mycroft-core/.venv/lib/python3.7/site-packages/pyee/_executor.py", line 56, in _callback
    self.emit('error', exc)
  File "/opt/mycroft-core/.venv/lib/python3.7/site-packages/pyee/_base.py", line 116, in emit
    self._emit_handle_potential_error(event, args[0] if args else None)
  File "/opt/mycroft-core/.venv/lib/python3.7/site-packages/pyee/_base.py", line 86, in _emit_handle_potential_error
    raise error
  File "/opt/hostedtoolcache/Python/3.7.12/x64/lib/python3.7/concurrent/futures/thread.py", line 57, in run
    result = self.fn(*self.args, **self.kwargs)
  File "/opt/mycroft-core/mycroft/audio/speech.py", line 77, in handle_speak
    chunks = tts.preprocess_utterance(utterance)
AttributeError: 'NoneType' object has no attribute 'preprocess_utterance'
2022-03-28 09:21:21.845 | ERROR    |  4683 | concurrent.futures | exception calling callback for <Future at 0x7f2f3918a290 state=finished raised AttributeError>
Traceback (most recent call last):
  File "/opt/hostedtoolcache/Python/3.7.12/x64/lib/python3.7/concurrent/futures/_base.py", line 324, in _invoke_callbacks
    callback(self)
  File "/opt/mycroft-core/.venv/lib/python3.7/site-packages/pyee/_executor.py", line 56, in _callback
    self.emit('error', exc)
  File "/opt/mycroft-core/.venv/lib/python3.7/site-packages/pyee/_base.py", line 116, in emit
    self._emit_handle_potential_error(event, args[0] if args else None)
  File "/opt/mycroft-core/.venv/lib/python3.7/site-packages/pyee/_base.py", line 86, in _emit_handle_potential_error
    raise error
  File "/opt/hostedtoolcache/Python/3.7.12/x64/lib/python3.7/concurrent/futures/thread.py", line 57, in run
    result = self.fn(*self.args, **self.kwargs)
  File "/opt/mycroft-core/mycroft/audio/speech.py", line 77, in handle_speak
    chunks = tts.preprocess_utterance(utterance)
AttributeError: 'NoneType' object has no attribute 'preprocess_utterance'
2022-03-28 09:21:22.239 | ERROR    |  4683 | concurrent.futures | exception calling callback for <Future at 0x7f2f39189ad0 state=finished raised AttributeError>
Traceback (most recent call last):
  File "/opt/hostedtoolcache/Python/3.7.12/x64/lib/python3.7/concurrent/futures/_base.py", line 324, in _invoke_callbacks
    callback(self)
  File "/opt/mycroft-core/.venv/lib/python3.7/site-packages/pyee/_executor.py", line 56, in _callback
    self.emit('error', exc)
  File "/opt/mycroft-core/.venv/lib/python3.7/site-packages/pyee/_base.py", line 116, in emit
    self._emit_handle_potential_error(event, args[0] if args else None)
  File "/opt/mycroft-core/.venv/lib/python3.7/site-packages/pyee/_base.py", line 86, in _emit_handle_potential_error
    raise error
  File "/opt/hostedtoolcache/Python/3.7.12/x64/lib/python3.7/concurrent/futures/thread.py", line 57, in run
    result = self.fn(*self.args, **self.kwargs)
  File "/opt/mycroft-core/mycroft/audio/speech.py", line 77, in handle_speak
    chunks = tts.preprocess_utterance(utterance)
AttributeError: 'NoneType' object has no attribute 'preprocess_utterance'
2022-03-28 09:21:22.640 | ERROR    |  4683 | concurrent.futures | exception calling callback for <Future at 0x7f2f391894d0 state=finished raised AttributeError>
Traceback (most recent call last):
  File "/opt/hostedtoolcache/Python/3.7.12/x64/lib/python3.7/concurrent/futures/_base.py", line 324, in _invoke_callbacks
    callback(self)
  File "/opt/mycroft-core/.venv/lib/python3.7/site-packages/pyee/_executor.py", line 56, in _callback
    self.emit('error', exc)
  File "/opt/mycroft-core/.venv/lib/python3.7/site-packages/pyee/_base.py", line 116, in emit
    self._emit_handle_potential_error(event, args[0] if args else None)
  File "/opt/mycroft-core/.venv/lib/python3.7/site-packages/pyee/_base.py", line 86, in _emit_handle_potential_error
    raise error
  File "/opt/hostedtoolcache/Python/3.7.12/x64/lib/python3.7/concurrent/futures/thread.py", line 57, in run
    result = self.fn(*self.args, **self.kwargs)
  File "/opt/mycroft-core/mycroft/audio/speech.py", line 77, in handle_speak
    chunks = tts.preprocess_utterance(utterance)
AttributeError: 'NoneType' object has no attribute 'preprocess_utterance'
2022-03-28 09:21:23.033 | ERROR    |  4683 | concurrent.futures | exception calling callback for <Future at 0x7f2f39185310 state=finished raised AttributeError>
Traceback (most recent call last):
  File "/opt/hostedtoolcache/Python/3.7.12/x64/lib/python3.7/concurrent/futures/_base.py", line 324, in _invoke_callbacks
    callback(self)
  File "/opt/mycroft-core/.venv/lib/python3.7/site-packages/pyee/_executor.py", line 56, in _callback
    self.emit('error', exc)
  File "/opt/mycroft-core/.venv/lib/python3.7/site-packages/pyee/_base.py", line 116, in emit
    self._emit_handle_potential_error(event, args[0] if args else None)
  File "/opt/mycroft-core/.venv/lib/python3.7/site-packages/pyee/_base.py", line 86, in _emit_handle_potential_error
    raise error
  File "/opt/hostedtoolcache/Python/3.7.12/x64/lib/python3.7/concurrent/futures/thread.py", line 57, in run
    result = self.fn(*self.args, **self.kwargs)
  File "/opt/mycroft-core/mycroft/audio/speech.py", line 77, in handle_speak
    chunks = tts.preprocess_utterance(utterance)
AttributeError: 'NoneType' object has no attribute 'preprocess_utterance'
2022-03-28 09:21:24.055 | ERROR    |  4683 | concurrent.futures | exception calling callback for <Future at 0x7f2f39185890 state=finished raised AttributeError>
Traceback (most recent call last):
  File "/opt/hostedtoolcache/Python/3.7.12/x64/lib/python3.7/concurrent/futures/_base.py", line 324, in _invoke_callbacks
    callback(self)
  File "/opt/mycroft-core/.venv/lib/python3.7/site-packages/pyee/_executor.py", line 56, in _callback
    self.emit('error', exc)
  File "/opt/mycroft-core/.venv/lib/python3.7/site-packages/pyee/_base.py", line 116, in emit
    self._emit_handle_potential_error(event, args[0] if args else None)
  File "/opt/mycroft-core/.venv/lib/python3.7/site-packages/pyee/_base.py", line 86, in _emit_handle_potential_error
    raise error
  File "/opt/hostedtoolcache/Python/3.7.12/x64/lib/python3.7/concurrent/futures/thread.py", line 57, in run
    result = self.fn(*self.args, **self.kwargs)
  File "/opt/mycroft-core/mycroft/audio/speech.py", line 77, in handle_speak
    chunks = tts.preprocess_utterance(utterance)
AttributeError: 'NoneType' object has no attribute 'preprocess_utterance'
2022-03-28 09:21:32.243 | ERROR    |  4683 | concurrent.futures | exception calling callback for <Future at 0x7f2f30d3b0d0 state=finished raised AttributeError>
Traceback (most recent call last):
  File "/opt/hostedtoolcache/Python/3.7.12/x64/lib/python3.7/concurrent/futures/_base.py", line 324, in _invoke_callbacks
    callback(self)
  File "/opt/mycroft-core/.venv/lib/python3.7/site-packages/pyee/_executor.py", line 56, in _callback
    self.emit('error', exc)
  File "/opt/mycroft-core/.venv/lib/python3.7/site-packages/pyee/_base.py", line 116, in emit
    self._emit_handle_potential_error(event, args[0] if args else None)
  File "/opt/mycroft-core/.venv/lib/python3.7/site-packages/pyee/_base.py", line 86, in _emit_handle_potential_error
    raise error
  File "/opt/hostedtoolcache/Python/3.7.12/x64/lib/python3.7/concurrent/futures/thread.py", line 57, in run
    result = self.fn(*self.args, **self.kwargs)
  File "/opt/mycroft-core/mycroft/audio/speech.py", line 77, in handle_speak
    chunks = tts.preprocess_utterance(utterance)
AttributeError: 'NoneType' object has no attribute 'preprocess_utterance'
2022-03-28 09:21:32.676 | ERROR    |  4683 | concurrent.futures | exception calling callback for <Future at 0x7f2f30d3b250 state=finished raised AttributeError>
Traceback (most recent call last):
  File "/opt/hostedtoolcache/Python/3.7.12/x64/lib/python3.7/concurrent/futures/_base.py", line 324, in _invoke_callbacks
    callback(self)
  File "/opt/mycroft-core/.venv/lib/python3.7/site-packages/pyee/_executor.py", line 56, in _callback
    self.emit('error', exc)
  File "/opt/mycroft-core/.venv/lib/python3.7/site-packages/pyee/_base.py", line 116, in emit
    self._emit_handle_potential_error(event, args[0] if args else None)
  File "/opt/mycroft-core/.venv/lib/python3.7/site-packages/pyee/_base.py", line 86, in _emit_handle_potential_error
    raise error
  File "/opt/hostedtoolcache/Python/3.7.12/x64/lib/python3.7/concurrent/futures/thread.py", line 57, in run
    result = self.fn(*self.args, **self.kwargs)
  File "/opt/mycroft-core/mycroft/audio/speech.py", line 77, in handle_speak
    chunks = tts.preprocess_utterance(utterance)
AttributeError: 'NoneType' object has no attribute 'preprocess_utterance'
2022-03-28 09:21:33.065 | ERROR    |  4683 | concurrent.futures | exception calling callback for <Future at 0x7f2f30d3bb90 state=finished raised AttributeError>
Traceback (most recent call last):
  File "/opt/hostedtoolcache/Python/3.7.12/x64/lib/python3.7/concurrent/futures/_base.py", line 324, in _invoke_callbacks
    callback(self)
  File "/opt/mycroft-core/.venv/lib/python3.7/site-packages/pyee/_executor.py", line 56, in _callback
    self.emit('error', exc)
  File "/opt/mycroft-core/.venv/lib/python3.7/site-packages/pyee/_base.py", line 116, in emit
    self._emit_handle_potential_error(event, args[0] if args else None)
  File "/opt/mycroft-core/.venv/lib/python3.7/site-packages/pyee/_base.py", line 86, in _emit_handle_potential_error
    raise error
  File "/opt/hostedtoolcache/Python/3.7.12/x64/lib/python3.7/concurrent/futures/thread.py", line 57, in run
    result = self.fn(*self.args, **self.kwargs)
  File "/opt/mycroft-core/mycroft/audio/speech.py", line 77, in handle_speak
    chunks = tts.preprocess_utterance(utterance)
AttributeError: 'NoneType' object has no attribute 'preprocess_utterance'
2022-03-28 09:21:33.423 | ERROR    |  4683 | concurrent.futures | exception calling callback for <Future at 0x7f2f30d44190 state=finished raised AttributeError>
Traceback (most recent call last):
  File "/opt/hostedtoolcache/Python/3.7.12/x64/lib/python3.7/concurrent/futures/_base.py", line 324, in _invoke_callbacks
    callback(self)
  File "/opt/mycroft-core/.venv/lib/python3.7/site-packages/pyee/_executor.py", line 56, in _callback
    self.emit('error', exc)
  File "/opt/mycroft-core/.venv/lib/python3.7/site-packages/pyee/_base.py", line 116, in emit
    self._emit_handle_potential_error(event, args[0] if args else None)
  File "/opt/mycroft-core/.venv/lib/python3.7/site-packages/pyee/_base.py", line 86, in _emit_handle_potential_error
    raise error
  File "/opt/hostedtoolcache/Python/3.7.12/x64/lib/python3.7/concurrent/futures/thread.py", line 57, in run
    result = self.fn(*self.args, **self.kwargs)
  File "/opt/mycroft-core/mycroft/audio/speech.py", line 77, in handle_speak
    chunks = tts.preprocess_utterance(utterance)
AttributeError: 'NoneType' object has no attribute 'preprocess_utterance'
2022-03-28 09:21:34.085 | ERROR    |  4683 | concurrent.futures | exception calling callback for <Future at 0x7f2f30d44910 state=finished raised AttributeError>
Traceback (most recent call last):
  File "/opt/hostedtoolcache/Python/3.7.12/x64/lib/python3.7/concurrent/futures/_base.py", line 324, in _invoke_callbacks
    callback(self)
  File "/opt/mycroft-core/.venv/lib/python3.7/site-packages/pyee/_executor.py", line 56, in _callback
    self.emit('error', exc)
  File "/opt/mycroft-core/.venv/lib/python3.7/site-packages/pyee/_base.py", line 116, in emit
    self._emit_handle_potential_error(event, args[0] if args else None)
  File "/opt/mycroft-core/.venv/lib/python3.7/site-packages/pyee/_base.py", line 86, in _emit_handle_potential_error
    raise error
  File "/opt/hostedtoolcache/Python/3.7.12/x64/lib/python3.7/concurrent/futures/thread.py", line 57, in run
    result = self.fn(*self.args, **self.kwargs)
  File "/opt/mycroft-core/mycroft/audio/speech.py", line 77, in handle_speak
    chunks = tts.preprocess_utterance(utterance)
AttributeError: 'NoneType' object has no attribute 'preprocess_utterance'
2022-03-28 09:21:34.470 | ERROR    |  4683 | concurrent.futures | exception calling callback for <Future at 0x7f2f30d44b50 state=finished raised AttributeError>
Traceback (most recent call last):
  File "/opt/hostedtoolcache/Python/3.7.12/x64/lib/python3.7/concurrent/futures/_base.py", line 324, in _invoke_callbacks
    callback(self)
  File "/opt/mycroft-core/.venv/lib/python3.7/site-packages/pyee/_executor.py", line 56, in _callback
    self.emit('error', exc)
  File "/opt/mycroft-core/.venv/lib/python3.7/site-packages/pyee/_base.py", line 116, in emit
    self._emit_handle_potential_error(event, args[0] if args else None)
  File "/opt/mycroft-core/.venv/lib/python3.7/site-packages/pyee/_base.py", line 86, in _emit_handle_potential_error
    raise error
  File "/opt/hostedtoolcache/Python/3.7.12/x64/lib/python3.7/concurrent/futures/thread.py", line 57, in run
    result = self.fn(*self.args, **self.kwargs)
  File "/opt/mycroft-core/mycroft/audio/speech.py", line 77, in handle_speak
    chunks = tts.preprocess_utterance(utterance)
AttributeError: 'NoneType' object has no attribute 'preprocess_utterance'
2022-03-28 09:21:41.900 | ERROR    |  4683 | concurrent.futures | exception calling callback for <Future at 0x7f2f30d483d0 state=finished raised AttributeError>
Traceback (most recent call last):
  File "/opt/hostedtoolcache/Python/3.7.12/x64/lib/python3.7/concurrent/futures/_base.py", line 324, in _invoke_callbacks
    callback(self)
  File "/opt/mycroft-core/.venv/lib/python3.7/site-packages/pyee/_executor.py", line 56, in _callback
    self.emit('error', exc)
  File "/opt/mycroft-core/.venv/lib/python3.7/site-packages/pyee/_base.py", line 116, in emit
    self._emit_handle_potential_error(event, args[0] if args else None)
  File "/opt/mycroft-core/.venv/lib/python3.7/site-packages/pyee/_base.py", line 86, in _emit_handle_potential_error
    raise error
  File "/opt/hostedtoolcache/Python/3.7.12/x64/lib/python3.7/concurrent/futures/thread.py", line 57, in run
    result = self.fn(*self.args, **self.kwargs)
  File "/opt/mycroft-core/mycroft/audio/speech.py", line 77, in handle_speak
    chunks = tts.preprocess_utterance(utterance)
AttributeError: 'NoneType' object has no attribute 'preprocess_utterance'
2022-03-28 09:21:42.919 | ERROR    |  4683 | concurrent.futures | exception calling callback for <Future at 0x7f2f30d48890 state=finished raised AttributeError>
Traceback (most recent call last):
  File "/opt/hostedtoolcache/Python/3.7.12/x64/lib/python3.7/concurrent/futures/_base.py", line 324, in _invoke_callbacks
    callback(self)
  File "/opt/mycroft-core/.venv/lib/python3.7/site-packages/pyee/_executor.py", line 56, in _callback
    self.emit('error', exc)
  File "/opt/mycroft-core/.venv/lib/python3.7/site-packages/pyee/_base.py", line 116, in emit
    self._emit_handle_potential_error(event, args[0] if args else None)
  File "/opt/mycroft-core/.venv/lib/python3.7/site-packages/pyee/_base.py", line 86, in _emit_handle_potential_error
    raise error
  File "/opt/hostedtoolcache/Python/3.7.12/x64/lib/python3.7/concurrent/futures/thread.py", line 57, in run
    result = self.fn(*self.args, **self.kwargs)
  File "/opt/mycroft-core/mycroft/audio/speech.py", line 77, in handle_speak
    chunks = tts.preprocess_utterance(utterance)
AttributeError: 'NoneType' object has no attribute 'preprocess_utterance'
2022-03-28 09:21:52.592 | ERROR    |  4683 | concurrent.futures | exception calling callback for <Future at 0x7f2f30d44810 state=finished raised AttributeError>
Traceback (most recent call last):
  File "/opt/hostedtoolcache/Python/3.7.12/x64/lib/python3.7/concurrent/futures/_base.py", line 324, in _invoke_callbacks
    callback(self)
  File "/opt/mycroft-core/.venv/lib/python3.7/site-packages/pyee/_executor.py", line 56, in _callback
    self.emit('error', exc)
  File "/opt/mycroft-core/.venv/lib/python3.7/site-packages/pyee/_base.py", line 116, in emit
    self._emit_handle_potential_error(event, args[0] if args else None)
  File "/opt/mycroft-core/.venv/lib/python3.7/site-packages/pyee/_base.py", line 86, in _emit_handle_potential_error
    raise error
  File "/opt/hostedtoolcache/Python/3.7.12/x64/lib/python3.7/concurrent/futures/thread.py", line 57, in run
    result = self.fn(*self.args, **self.kwargs)
  File "/opt/mycroft-core/mycroft/audio/speech.py", line 77, in handle_speak
    chunks = tts.preprocess_utterance(utterance)
AttributeError: 'NoneType' object has no attribute 'preprocess_utterance'
2022-03-28 09:22:02.892 | ERROR    |  4683 | concurrent.futures | exception calling callback for <Future at 0x7f2f30d44710 state=finished raised AttributeError>
Traceback (most recent call last):
  File "/opt/hostedtoolcache/Python/3.7.12/x64/lib/python3.7/concurrent/futures/_base.py", line 324, in _invoke_callbacks
    callback(self)
  File "/opt/mycroft-core/.venv/lib/python3.7/site-packages/pyee/_executor.py", line 56, in _callback
    self.emit('error', exc)
  File "/opt/mycroft-core/.venv/lib/python3.7/site-packages/pyee/_base.py", line 116, in emit
    self._emit_handle_potential_error(event, args[0] if args else None)
  File "/opt/mycroft-core/.venv/lib/python3.7/site-packages/pyee/_base.py", line 86, in _emit_handle_potential_error
    raise error
  File "/opt/hostedtoolcache/Python/3.7.12/x64/lib/python3.7/concurrent/futures/thread.py", line 57, in run
    result = self.fn(*self.args, **self.kwargs)
  File "/opt/mycroft-core/mycroft/audio/speech.py", line 77, in handle_speak
    chunks = tts.preprocess_utterance(utterance)
AttributeError: 'NoneType' object has no attribute 'preprocess_utterance'
2022-03-28 09:22:13.422 | ERROR    |  4683 | concurrent.futures | exception calling callback for <Future at 0x7f2f30d440d0 state=finished raised AttributeError>
Traceback (most recent call last):
  File "/opt/hostedtoolcache/Python/3.7.12/x64/lib/python3.7/concurrent/futures/_base.py", line 324, in _invoke_callbacks
    callback(self)
  File "/opt/mycroft-core/.venv/lib/python3.7/site-packages/pyee/_executor.py", line 56, in _callback
    self.emit('error', exc)
  File "/opt/mycroft-core/.venv/lib/python3.7/site-packages/pyee/_base.py", line 116, in emit
    self._emit_handle_potential_error(event, args[0] if args else None)
  File "/opt/mycroft-core/.venv/lib/python3.7/site-packages/pyee/_base.py", line 86, in _emit_handle_potential_error
    raise error
  File "/opt/hostedtoolcache/Python/3.7.12/x64/lib/python3.7/concurrent/futures/thread.py", line 57, in run
    result = self.fn(*self.args, **self.kwargs)
  File "/opt/mycroft-core/mycroft/audio/speech.py", line 77, in handle_speak
    chunks = tts.preprocess_utterance(utterance)
AttributeError: 'NoneType' object has no attribute 'preprocess_utterance'
2022-03-28 09:22:23.491 | ERROR    |  4683 | concurrent.futures | exception calling callback for <Future at 0x7f2f30d3b690 state=finished raised AttributeError>
Traceback (most recent call last):
  File "/opt/hostedtoolcache/Python/3.7.12/x64/lib/python3.7/concurrent/futures/_base.py", line 324, in _invoke_callbacks
    callback(self)
  File "/opt/mycroft-core/.venv/lib/python3.7/site-packages/pyee/_executor.py", line 56, in _callback
    self.emit('error', exc)
  File "/opt/mycroft-core/.venv/lib/python3.7/site-packages/pyee/_base.py", line 116, in emit
    self._emit_handle_potential_error(event, args[0] if args else None)
  File "/opt/mycroft-core/.venv/lib/python3.7/site-packages/pyee/_base.py", line 86, in _emit_handle_potential_error
    raise error
  File "/opt/hostedtoolcache/Python/3.7.12/x64/lib/python3.7/concurrent/futures/thread.py", line 57, in run
    result = self.fn(*self.args, **self.kwargs)
  File "/opt/mycroft-core/mycroft/audio/speech.py", line 77, in handle_speak
    chunks = tts.preprocess_utterance(utterance)
AttributeError: 'NoneType' object has no attribute 'preprocess_utterance'
2022-03-28 09:22:23.835 | ERROR    |  4683 | concurrent.futures | exception calling callback for <Future at 0x7f2f30d3b810 state=finished raised AttributeError>
Traceback (most recent call last):
  File "/opt/hostedtoolcache/Python/3.7.12/x64/lib/python3.7/concurrent/futures/_base.py", line 324, in _invoke_callbacks
    callback(self)
  File "/opt/mycroft-core/.venv/lib/python3.7/site-packages/pyee/_executor.py", line 56, in _callback
    self.emit('error', exc)
  File "/opt/mycroft-core/.venv/lib/python3.7/site-packages/pyee/_base.py", line 116, in emit
    self._emit_handle_potential_error(event, args[0] if args else None)
  File "/opt/mycroft-core/.venv/lib/python3.7/site-packages/pyee/_base.py", line 86, in _emit_handle_potential_error
    raise error
  File "/opt/hostedtoolcache/Python/3.7.12/x64/lib/python3.7/concurrent/futures/thread.py", line 57, in run
    result = self.fn(*self.args, **self.kwargs)
  File "/opt/mycroft-core/mycroft/audio/speech.py", line 77, in handle_speak
    chunks = tts.preprocess_utterance(utterance)
AttributeError: 'NoneType' object has no attribute 'preprocess_utterance'
2022-03-28 09:22:24.227 | ERROR    |  4683 | concurrent.futures | exception calling callback for <Future at 0x7f2f30d3b450 state=finished raised AttributeError>
Traceback (most recent call last):
  File "/opt/hostedtoolcache/Python/3.7.12/x64/lib/python3.7/concurrent/futures/_base.py", line 324, in _invoke_callbacks
    callback(self)
  File "/opt/mycroft-core/.venv/lib/python3.7/site-packages/pyee/_executor.py", line 56, in _callback
    self.emit('error', exc)
  File "/opt/mycroft-core/.venv/lib/python3.7/site-packages/pyee/_base.py", line 116, in emit
    self._emit_handle_potential_error(event, args[0] if args else None)
  File "/opt/mycroft-core/.venv/lib/python3.7/site-packages/pyee/_base.py", line 86, in _emit_handle_potential_error
    raise error
  File "/opt/hostedtoolcache/Python/3.7.12/x64/lib/python3.7/concurrent/futures/thread.py", line 57, in run
    result = self.fn(*self.args, **self.kwargs)
  File "/opt/mycroft-core/mycroft/audio/speech.py", line 77, in handle_speak
    chunks = tts.preprocess_utterance(utterance)
AttributeError: 'NoneType' object has no attribute 'preprocess_utterance'
2022-03-28 09:22:34.526 | ERROR    |  4683 | concurrent.futures | exception calling callback for <Future at 0x7f2f30d2ff50 state=finished raised AttributeError>
Traceback (most recent call last):
  File "/opt/hostedtoolcache/Python/3.7.12/x64/lib/python3.7/concurrent/futures/_base.py", line 324, in _invoke_callbacks
    callback(self)
  File "/opt/mycroft-core/.venv/lib/python3.7/site-packages/pyee/_executor.py", line 56, in _callback
    self.emit('error', exc)
  File "/opt/mycroft-core/.venv/lib/python3.7/site-packages/pyee/_base.py", line 116, in emit
    self._emit_handle_potential_error(event, args[0] if args else None)
  File "/opt/mycroft-core/.venv/lib/python3.7/site-packages/pyee/_base.py", line 86, in _emit_handle_potential_error
    raise error
  File "/opt/hostedtoolcache/Python/3.7.12/x64/lib/python3.7/concurrent/futures/thread.py", line 57, in run
    result = self.fn(*self.args, **self.kwargs)
  File "/opt/mycroft-core/mycroft/audio/speech.py", line 77, in handle_speak
    chunks = tts.preprocess_utterance(utterance)
AttributeError: 'NoneType' object has no attribute 'preprocess_utterance'
Exception ignored in: <module 'threading' from '/opt/hostedtoolcache/Python/3.7.12/x64/lib/python3.7/threading.py'>
Traceback (most recent call last):
  File "/opt/hostedtoolcache/Python/3.7.12/x64/lib/python3.7/threading.py", line 1307, in _shutdown
    lock.acquire()
KeyboardInterrupt
