2022-03-28 09:19:42.058 | INFO     |  4689 | __main__:create_enclosure:55 | Creating generic enclosure, platform='None'
2022-03-28 09:19:42.065 | INFO     |  4689 | mycroft.messagebus.load_config:load_message_bus_config:33 | Loading message bus configs
2022-03-28 09:19:42.082 | INFO     |  4689 | mycroft.client.enclosure.base:create_gui_service:473 | Starting message bus for GUI...
2022-03-28 09:19:42.095 | INFO     |  4689 | mycroft.client.enclosure.base:create_gui_service:483 | GUI Message bus started!
2022-03-28 09:19:42.095 | INFO     |  4689 | mycroft.enclosure.display_manager:init_display_manager_bus_connection:152 | Connecting display manager to messagebus
2022-03-28 09:19:42.096 | INFO     |  4689 | mycroft.messagebus.load_config:load_message_bus_config:33 | Loading message bus configs
2022-03-28 09:19:42.103 | ERROR    |  4689 | mycroft_bus_client.client.client | === ConnectionRefusedError(111, 'Connection refused') ===
Traceback (most recent call last):
  File "/opt/mycroft-core/.venv/lib/python3.7/site-packages/websocket/_app.py", line 318, in run_forever
    proxy_type=proxy_type)
  File "/opt/mycroft-core/.venv/lib/python3.7/site-packages/websocket/_core.py", line 250, in connect
    options.pop('socket', None))
  File "/opt/mycroft-core/.venv/lib/python3.7/site-packages/websocket/_http.py", line 130, in connect
    sock = _open_socket(addrinfo_list, options.sockopt, options.timeout)
  File "/opt/mycroft-core/.venv/lib/python3.7/site-packages/websocket/_http.py", line 208, in _open_socket
    raise err
  File "/opt/mycroft-core/.venv/lib/python3.7/site-packages/websocket/_http.py", line 185, in _open_socket
    sock.connect(address)
ConnectionRefusedError: [Errno 111] Connection refused
2022-03-28 09:19:42.104 | ERROR    |  4689 | mycroft_bus_client.client.client | Exception closing websocket: ConnectionRefusedError(111, 'Connection refused')
2022-03-28 09:19:42.104 | WARNING  |  4689 | mycroft_bus_client.client.client | Message Bus Client will reconnect in 5.0 seconds.
2022-03-28 09:19:42.159 | INFO     |  4689 | mycroft_bus_client.client.client | Connected
2022-03-28 09:19:42.168 | INFO     |  4689 | mycroft.util.process_utils:start_message_bus_client:155 | Connected to messagebus
2022-03-28 09:19:42.168 | INFO     |  4689 | __main__:on_ready:26 | Enclosure started!
2022-03-28 09:19:47.109 | INFO     |  4689 | mycroft_bus_client.client.client | Connected
2022-03-28 09:22:22.234 | ERROR    |  4689 | concurrent.futures | exception calling callback for <Future at 0x7f5bde5fa550 state=finished raised Exception>
Traceback (most recent call last):
  File "/opt/hostedtoolcache/Python/3.7.12/x64/lib/python3.7/concurrent/futures/_base.py", line 324, in _invoke_callbacks
    callback(self)
  File "/opt/mycroft-core/.venv/lib/python3.7/site-packages/pyee/_executor.py", line 56, in _callback
    self.emit('error', exc)
  File "/opt/mycroft-core/.venv/lib/python3.7/site-packages/pyee/_base.py", line 116, in emit
    self._emit_handle_potential_error(event, args[0] if args else None)
  File "/opt/mycroft-core/.venv/lib/python3.7/site-packages/pyee/_base.py", line 86, in _emit_handle_potential_error
    raise error
  File "/opt/hostedtoolcache/Python/3.7.12/x64/lib/python3.7/concurrent/futures/thread.py", line 57, in run
    result = self.fn(*self.args, **self.kwargs)
  File "/opt/mycroft-core/mycroft/client/enclosure/generic/__init__.py", line 72, in is_device_ready
    raise Exception('Timeout waiting for services start.')
Exception: Timeout waiting for services start.
2022-03-28 09:22:40.826 | INFO     |  4689 | __main__:on_stopping:30 | Enclosure is shutting down...
